Workbook

Sheet 使用说明
A1: RIMS数据归档平台Phase1 · WBS工作分解结构（AI Native版）— 使用说明
A3: 一、项目与团队
A4: 项目 | B4: RIMS退役系统数据归档管理平台 · Phase1「基础归档与查询」：8大模块、26项功能（详见源文件《项目执行计划 (3).xlsx》Scope-Phase1）+ 非功能需求（性能/安全/合规/可用性/容量）统一排程
A5: 团队与投入 | B5: V2.1排期口径（「功能拆解估算」直估297.5人天×AI执行系数=212.3人天）：Mandy三职排期68.2、Wade 64.8、DevB 65.0、Mark 14.4；系数按每行AI参与方式分档（AI生成+人工审核×0.65／AI辅助×0.75／自动化流水线×0.90／人工主导×1.0／测试左移×0.60），WBS各行Q列有直估对照。
A6: Mandy工作量口径 | B6: V2.1采用测试左移（AI用例随BA澄清先行、随CI构建持续验证）：功能测试直估38.75×0.60；SLC初稿随开发滚动AI反生成×0.75、7.1定稿收口；三职排期68.2人天（直估98）。
A7: PM投入分布 | B7: Mark 15人天贯穿式分布：启动会1 + 每周项目例会12次×0.5=6 + 开发期每日任务同步会约2 + 进度/风险跟踪2.5 + 里程碑评审2.5 + 交付确认收尾1（最后1天在12/16项目结束时使用）
A8: 周期 | B8: 2026/9/14（周一）启动 → 2026/12/31（周四）交付（V2.1），共73个工作日/人；M1=9/22、M2=9/30、M3=11/5、M4=12/16、M6(UAT)=12/17、M5(冻结评审)=12/25、M7=12/31；12/28~31生产部署+全量迁移窗口。
A9: 二、排期规则
A10: 开工日 | B10: 9/14（周一）
A11: 不排任务日 | B11: 周末（周六/周日）；中秋节 9/25（周五）~9/27（周日）；国庆节 10/1（周四）~10/7（周三）。假期合计损失6个工作日，任务自动顺延
A12: 调休补班日 | B12: 官方补班日 9/20（周日）、10/10（周六）逢周末，按约定同样不排任务；若进度落后可启用为备用赶工日
A13: 与原计划对应 | B13: 原《项目执行计划》185人天/62工作日 → V2.1：任务结构=「功能拆解估算」25功能×72子任务（按角色拆行）+N1~N5非功能组+环节；直估297.5人天经AI执行系数折算为212.3人天/73工作日，交付2026/12/31。折算与8项DevB→Wade瓶颈迁移、增量接入/复盘文档移上线后，是按期交付的三项前提（详见「功能拆解估算」页V2.1说明）。
A14: 三、AI Native模式（与模板传统模式的差异）
A15: 总体 | B15: 模板为传统瀑布（需求→设计→编码→测试→上线，人工编码+人工评审）；本版按AI Native（Vibe Coding）重排：AI生成+人工审核为主线，质量靠门禁与外部评审兜底
A16: 项目初始化 | B16: 项目启动即前置（3.3 N1工程基座：仓库/规范/前端骨架/四道门禁CI/CD + 3.4 N4部署流水线与测试环境先期部署）：先立环境与规矩再生成代码。部署节奏：Azure DevOps连接K8s，测试环境早期先部署（3.4，M3前就绪，流水线自动更新）、生产环境终期部署（8.1，带审批门禁），不用Helm。
A17: 非功能需求 | B17: 功能（26项）与非功能统一排程：NFR基线随SRS冻结（2.2.1，M1=9/24）→NFR测试可执行化（2.3.1）→非功能设计定稿（3.2.7）→N3全局非功能实现（5.14）→N2质量治理清零（6.1）→系统测试轮1（6.4.2）→性能/安全专项+部署预演+迁移预跑（7.2）→UAT（7.1.3）→生产就绪评审（7.2.9）→部署（8.1）。
A18: 需求 | B18: 人工访谈澄清优先级后，SRS由AI生成初稿+人工评审基线（🤖见2.2.1）
A19: 设计 | B19: 架构图已预确认→设计阶段仅收尾定稿+ADR留痕；新增「AI工程基线」（3.1.1工具链/规范、3.1.2四道安全门禁CI）替代传统前置详细设计
A20: 开发 | B20: Vibe Coding：AI生成代码+人工审核+四道门禁硬卡点合入；每周五下午固定0.5天技术债偿还；外部关键模块评审2次（10/9、11/11）
A21: 测试 | B21: AI生成测试用例+人工补充边界/越权用例；AI辅助执行与缺陷聚类（轮1、全量、UAT三级）
A22: 文档 | B22: AI反生成（代码/演示→手册）+人工润色，随模块滚动产出，不再后置到上线后
A23: 四、表格说明
A24: 新增列 | B24: 「工作量(人天)」＝实际人力投入（汇总行自动汇总）；「AI参与方式」＝该任务的AI参与程度（AI生成+人工审核 / AI辅助 / 人工主导 / 自动化流水线）
A25: 工期(天) | B25: ＝起止日期间的排产工作日数（已扣除周末/中秋/国庆），非自然日跨度；贯穿型任务工期为跨度假定的日历工作跨度，实际投入以工作量列为准
A26: 里程碑 | B26: 任务名称含「◆」且金色底纹＝里程碑：M1=9/22需求冻结、M2=9/30设计冻结、M3=11/5批次1样本端到端（测试环境K8s演示）、M4=12/16编码完成、M6=12/17 UAT签字、M5=12/25代码冻结+就绪评审（AI Native并行：全量测试与治理并行收口，UAT先于冻结评审完成）、M7=12/31生产上线交付。
A27: 自动化 | B27: 状态/优先级下拉选择；超期未完成整行自动标红；进度列数据条；一级任务蓝底汇总；「进度汇总」页自动统计
A28: 功能覆盖对照 | B28: 「26项功能覆盖对照」页：源文件Scope-Phase1的26项功能（F01-01~F08-05）与WBS任务逐项对照（主开发/界面协作/走查/全量测试/负责人/计划完成日），功能名与源文件一字不差，可直接用于功能完整性验收
A29: 其他页签 | B29: 「里程碑计划」「资源负荷与日历」「WBS词典」「进度汇总」配合使用；如需甘特图可将WBS编号+起止日期导出到Project/飞书项目
A30: 功能视角分解 | B30: 按功能维度查看：26项功能×（BA/开发A/开发B/测试/文档）五类角色各自的工作内容与人天（V2.0=「功能拆解估算」直估原值），另有9类公共支撑行（需求/基座/架构/集成/测试/专项/上线/管理，挂新WBS组编码）；底部与WBS分解V2.0合计297.5人天自动对账
A35: 功能拆解估算 | B35: 子任务级直估：模块→功能→子任务三层结构（模块列与功能列均为纵向合并单元格），25项功能×72子任务 + 非功能与工程支撑×23子任务（N1框架初始化与基座/N2 ESLint·SonarLint·SAST代码质量治理/N3性能·鉴权·可观测·容量/N4部署运维），按BA/开发A/开发B/测试/SLC文档独立估人天；底部附与计划口径对照、AI提效折算与工作量合理性复查
A39: V2.1排期说明 | B39: 本版WBS分解（V2.1）按「功能拆解估算」页的任务与直估人天排期，交付锁定2026年内（12/31）：①开发任务=25功能×72子任务按角色拆行+非功能N1~N5+环节；②每行人天=直估×AI执行系数（AI生成×0.65/AI辅助×0.75/自动化×0.9/人工×1.0/测试左移×0.60，Q列有直估对照），合计297.5→214.3人天；③并行化：测试左移、SLC随开发滚动、N2治理随开发持续、CC演练与批次2并行、全量测试与冻结并行（M6先于M5）；④DevB瓶颈化解：8项应用/中间件任务移Wade，增量接入与复盘文档移上线后（B计划）；⑤测试环境（K8s）3.4先期部署、生产8.1终期部署（带审批），不用Helm。

Sheet WBS分解
A1: RIMS数据归档平台Phase1 · 项目工作分解结构（WBS）表 — AI Native版 · V2.1按「功能拆解估算」排期（AI Native执行折算，交付2026/12/30前）
A2: 项目名称：RIMS退役系统数据归档平台·Phase1（基础归档与查询） | F2: 项目经理：Mark | I2: 编制日期：2026/9/2 版本：V2.1（直估×AI执行系数排期） 窗口：2026/9/14 → 2026/12/31（不跨年）
A3: WBS编号 | B3: 任务名称 | C3: 层级 | D3: 交付物/成果 | E3: 负责人 | F3: 开始日期 | G3: 结束日期 | H3: 工期(天) | I3: 工作量(人天) | J3: AI参与方式 | K3: 前置任务 | L3: 状态 | M3: 进度 | N3: 优先级 | O3: 预算(元) | P3: 实际成本(元) | Q3: 备注
A4: 1 | B4: 项目管理（贯穿全周期·15人天） | C4: 1 | E4: Mark | F4: 46279 | G4: 46387 | H4: 73 | I4: =ROUND(SUMPRODUCT(($C$5:$C$14=3)*(LEFT($A$5:$A$14,LEN(A4)+1)=A4&".")*$I$5:$I$14),2)
A5: 1.1 | B5: 项目启动 | C5: 2 | E5: Mark | F5: 46279 | G5: 46279 | H5: 1 | I5: =ROUND(SUMPRODUCT(($C$6:$C$6=3)*(LEFT($A$6:$A$6,LEN(A5)+1)=A5&".")*$I$6:$I$6),2)
A6: 1.1.1 | B6: 项目启动会与开发模式交底（范围/总体计划/门禁规则/RACI） | C6: 3 | D6: 启动会纪要、RACI矩阵 | E6: Mark | F6: 46279 | G6: 46279 | H6: 1 | I6: 1 | J6: 人工主导 | Q6: 直估1·AI执行×1
A7: 1.2 | B7: 项目例会与进度跟踪（贯穿执行期） | C7: 2 | E7: Mandy/Mark | F7: 46286 | G7: 46386 | H7: 67 | I7: =ROUND(SUMPRODUCT(($C$8:$C$12=3)*(LEFT($A$8:$A$12,LEN(A7)+1)=A7&".")*$I$8:$I$12),2)
A8: 1.2.1 | B8: 每周项目例会（进度/风险/资源同步，对照进度基线） | C8: 3 | E8: Mark | F8: 46286 | G8: 46386 | H8: 67 | I8: 6 | J8: 人工主导 | Q8: 直估6·AI执行×1
A9: 1.2.2 | B9: 开发期每日任务同步会（每个工作日约30分钟：当日任务/阻塞/次日计划） | C9: 3 | E9: Mark | F9: 46286 | G9: 46381 | H9: 64 | I9: 2 | J9: 人工主导 | Q9: 直估2·AI执行×1
A10: 1.2.3 | B10: 进度跟踪与风险变更管理（进度计划更新/风险登记册/变更日志/外部依赖跟催） | C10: 3 | E10: Mark | F10: 46286 | G10: 46386 | H10: 67 | I10: 1.88 | J10: AI辅助 | Q10: 直估2.5·AI执行×0.75
A11: 1.2.4 | B11: 里程碑评审会组织（M1~M6） | C11: 3 | E11: Mark | F11: 46287 | G11: 46373 | H11: 57 | I11: 2.5 | J11: 人工主导 | Q11: 直估2.5·AI执行×1
A12: 1.2.5 | B12: 会议纪要与项目文档整理（配合PM，贯穿全周期） | C12: 3 | E12: Mandy | F12: 46286 | G12: 46386 | H12: 67 | I12: 0.75 | J12: AI辅助 | Q12: 直估1·AI执行×0.75
A13: 1.3 | B13: 项目收尾 | C13: 2 | E13: Mark | F13: 46387 | G13: 46387 | H13: 1 | I13: =ROUND(SUMPRODUCT(($C$14:$C$14=3)*(LEFT($A$14:$A$14,LEN(A13)+1)=A13&".")*$I$14:$I$14),2)
A14: 1.3.1 | B14: 项目交付确认与总结会◆M7 | C14: 3 | D14: 交付确认单 | E14: Mark | F14: 46387 | G14: 46387 | H14: 1 | I14: 1 | J14: 人工主导 | Q14: 直估1·AI执行×1
A15: 2 | B15: 需求与分析（AI辅助） | C15: 1 | E15: Mandy | F15: 46279 | G15: 46381 | H15: 69 | I15: =ROUND(SUMPRODUCT(($C$16:$C$28=3)*(LEFT($A$16:$A$28,LEN(A15)+1)=A15&".")*$I$16:$I$28),2)
A16: 2.1 | B16: 2.1 需求调研 | C16: 2 | E16: Mandy | F16: 46279 | G16: 46283 | H16: 5 | I16: =ROUND(SUMPRODUCT(($C$17:$C$19=3)*(LEFT($A$17:$A$19,LEN(A16)+1)=A16&".")*$I$17:$I$19),2)
A17: 2.1.1 | B17: 业务访谈3场（业务方×2+合规法务×1）+AI整理纪要 | C17: 3 | E17: Mandy | F17: 46279 | G17: 46280 | H17: 2 | I17: 1.5 | J17: AI辅助 | Q17: 直估2·AI执行×0.75
A18: 2.1.2 | B18: 26项功能逐条澄清+P0/P1/P2优先级标定 | C18: 3 | E18: Mandy | F18: 46280 | G18: 46282 | H18: 3 | I18: 2 | J18: 人工主导 | Q18: 直估2·AI执行×1
A19: 2.1.3 | B19: 核心页面原型草图（检索/迁移任务/处置） | C19: 3 | E19: Mandy | F19: 46282 | G19: 46283 | H19: 2 | I19: 0.65 | J19: AI生成+人工审核 | Q19: 直估1·AI执行×0.65
A20: 2.2 | B20: 2.2 需求定义与基线 | C20: 2 | E20: Mandy | F20: 46283 | G20: 46287 | H20: 3 | I20: =ROUND(SUMPRODUCT(($C$21:$C$22=3)*(LEFT($A$21:$A$22,LEN(A20)+1)=A20&".")*$I$21:$I$22),2)
A21: 2.2.1 | B21: AI生成SRS初稿（26项功能+非功能需求NFR：数据流图/归档范围矩阵/保留期矩阵+性能·安全·合规·容量基线） | C21: 3 | E21: Mandy | F21: 46283 | G21: 46286 | H21: 2 | I21: 1.62 | J21: AI生成+人工审核 | Q21: 直估2.5·AI执行×0.65
A22: 2.2.2 | B22: SRS评审与需求基线冻结◆M1 | C22: 3 | D22: SRS V1.0、基线确认单 | E22: Mandy | F22: 46287 | G22: 46287 | H22: 1 | I22: 1 | J22: 人工主导 | K22: 2.2.1 | Q22: 直估1·AI执行×1
A23: 2.3 | B23: 2.3 测试需求与非功能需求 | C23: 2 | E23: Mandy | F23: 46288 | G23: 46295 | H23: 5 | I23: =ROUND(SUMPRODUCT(($C$24:$C$26=3)*(LEFT($A$24:$A$26,LEN(A23)+1)=A23&".")*$I$24:$I$26),2)
A24: 2.3.1 | B24: NFR测试可执行化（NFR基线细化为可测验收标准：检索响应/导出吞吐/并发/越权与掩码旁路用例） | C24: 3 | E24: Mandy | F24: 46288 | G24: 46288 | H24: 1 | I24: 0.75 | J24: AI辅助 | K24: 2.2.2 | Q24: 直估1·AI执行×0.75
A25: 2.3.2 | B25: 测试计划框架+CC（Caring Center）验证场景清单 | C25: 3 | E25: Mandy | F25: 46288 | G25: 46289 | H25: 2 | I25: 1 | J25: 人工主导 | K25: 2.2.2 | Q25: 直估1·AI执行×1
A26: 2.3.3 | B26: AI生成测试用例首批（F01迁移/F08用户权限系列）——AI用例生成能力试点（9/30落地验证） | C26: 3 | E26: Mandy | F26: 46294 | G26: 46295 | H26: 2 | I26: 0.98 | J26: AI生成+人工审核 | K26: 2.3.1,2.3.2 | Q26: 直估1.5·AI执行×0.65
A27: 2.4 | B27: 2.4 需求贯穿支持 | C27: 2 | E27: Mandy | F27: 46286 | G27: 46381 | H27: 64 | I27: =ROUND(SUMPRODUCT(($C$28:$C$28=3)*(LEFT($A$28:$A$28,LEN(A27)+1)=A27&".")*$I$28:$I$28),2)
A28: 2.4.1 | B28: 需求澄清与变更支持（贯穿开发期：功能+非功能） | C28: 3 | E28: Mandy | F28: 46286 | G28: 46381 | H28: 64 | I28: 0.75 | J28: AI辅助 | Q28: 直估1·AI执行×0.75
A29: 3 | B29: 架构、设计与工程基座（含测试环境先期部署） | C29: 1 | E29: DevB/Mandy/Wade | F29: 46279 | G29: 46304 | H29: 14 | I29: =ROUND(SUMPRODUCT(($C$30:$C$61=3)*(LEFT($A$30:$A$61,LEN(A29)+1)=A29&".")*$I$30:$I$61),2)
A30: 3.1 | B30: 3.1 架构与接口定稿 | C30: 2 | E30: Wade | F30: 46288 | G30: 46295 | H30: 5 | I30: =ROUND(SUMPRODUCT(($C$31:$C$35=3)*(LEFT($A$31:$A$35,LEN(A30)+1)=A30&".")*$I$31:$I$35),2)
A31: 3.1.1 | B31: UC权限模型与F05查询配置模型设计（RBAC+Unity Catalog/元数据驱动动态渲染） | C31: 3 | E31: Wade | F31: 46288 | G31: 46289 | H31: 2 | I31: 2 | J31: 人工主导 | K31: 2.2.2 | Q31: 直估2·AI执行×1
A32: 3.1.2 | B32: 平台资源验收（ADLS/SQL DB/Databricks/Key Vault连通性验证） | C32: 3 | E32: Wade | F32: 46293 | G32: 46293 | H32: 1 | I32: 0.5 | J32: 人工主导 | Q32: 直估0.5·AI执行×1
A33: 3.1.3 | B33: 总体架构终稿+模块接口定义（按功能模块划分A/B边界） | C33: 3 | D33: 架构设计文档V1.0、接口定义 | E33: Wade | F33: 46293 | G33: 46294 | H33: 2 | I33: 0.75 | J33: AI辅助 | Q33: 直估1·AI执行×0.75
A34: 3.1.4 | B34: 外部架构评审#1（P0末，2h）+意见落实 | C34: 3 | E34: Wade | F34: 46294 | G34: 46294 | H34: 1 | I34: 0.5 | J34: 人工主导 | Q34: 直估0.5·AI执行×1
A35: 3.1.5 | B35: 设计评审通过+模块接口冻结◆M2 | C35: 3 | D35: 设计评审纪要 | E35: Wade | F35: 46295 | G35: 46295 | H35: 1 | I35: 0.5 | J35: 人工主导 | K35: 3.1.3,3.1.4 | Q35: 直估0.5·AI执行×1
A36: 3.2 | B36: 3.2 数据与后端设计 | C36: 2 | E36: DevB | F36: 46279 | G36: 46293 | H36: 10 | I36: =ROUND(SUMPRODUCT(($C$37:$C$43=3)*(LEFT($A$37:$A$43,LEN(A36)+1)=A36&".")*$I$37:$I$43),2)
A37: 3.2.1 | B37: 目标数据模型预设计（RAW→CURATED→LAKE→SERVE四层表结构草案，与访谈澄清并行、按Scope源文件预设计） | C37: 3 | E37: DevB | F37: 46279 | G37: 46280 | H37: 2 | I37: 1.5 | J37: AI辅助 | Q37: 直估2·AI执行×0.75
A38: 3.2.2 | B38: 外部依赖前置：平台资源申请+CC只读账号申请 | C38: 3 | D38: 申请单+回执 | E38: DevB | F38: 46280 | G38: 46281 | H38: 2 | I38: 1 | J38: 人工主导 | Q38: 直估1·AI执行×1
A39: 3.2.3 | B39: 元数据库建库脚本（35表DDL草案） | C39: 3 | E39: DevB | F39: 46281 | G39: 46282 | H39: 2 | I39: 1.3 | J39: AI生成+人工审核 | Q39: 直估2·AI执行×0.65
A40: 3.2.4 | B40: 湖仓分层设计细化（分区sys_id+日期/Parquet+ZSTD/湖与附件存储划分） | C40: 3 | E40: DevB | F40: 46282 | G40: 46286 | H40: 3 | I40: 1.5 | J40: AI辅助 | Q40: 直估2·AI执行×0.75
...

Sheet 26项功能覆盖对照
A1: 26项功能覆盖对照（源文件Scope-Phase1 ↔ WBS，逐项可追溯）
A2: 功能编号 | B2: 模块 | C2: 业务场景 | D2: 关键功能 | E2: 具体功能（与源文件一致） | F2: 功能描述（源文件） | G2: 主开发任务(WBS) | H2: 界面/协作任务(WBS) | I2: 走查任务(WBS) | J2: 全量测试 | K2: 开发负责人 / 计划完成
A3: F01-01 | B3: 模块1·存量历史数据迁移与标准化 | C3: 退役系统历史数据全量入库归档 | D3: 历史数据批量导入 | E3: 结构化历史数据批量导入 | F3: 支持从退役系统批量提取结构化历史数据，并按照既定迁移范围和映射规则导入RIMS。 | G3: 4.6 | H3: 同组·前端行 | I3: 同组·测试行 | J3: 7.1.1 | K3: Wade/DevB / 10/30
A4: F01-02 | B4: 模块1·存量历史数据迁移与标准化 | C4: 退役系统历史数据全量入库归档 | D4: 历史数据批量导入 | E4: 非结构化文件及离线包批量导入 | F4: 支持从多种文件来源和离线介质批量导入附件、普通文件、数据库备份包及压缩归档包，并保障大文件及传输中断场景下的可靠导入、原始属性保留和文件包解析。 | G4: 4.7 | H4: 同组·前端行 | I4: 同组·测试行 | J4: 7.1.1 | K4: Wade/DevB / 11/03
A5: F01-03 | B5: 模块1·存量历史数据迁移与标准化 | C5: 退役系统历史数据全量入库归档 | D5: 迁移规则配置 | E5: 数据导入规则配置 | F5: 面向退役系统迁移项目，配置源数据与RIMS标准字段的对应关系、格式转换和校验规则，并在导入过程中执行。 | G5: 4.8 | H5: 同组·前端行 | I5: 同组·测试行 | J5: 7.1.1 | K5: Wade/DevB / 11/05
A6: F01-04 | B6: 模块1·存量历史数据迁移与标准化 | C6: 确保迁移过程数据完整可追溯 | D6: 迁移完整性校验 | E6: 迁移前完整性基准记录 | F6: 在迁移前记录文件或数据集的完整性校验信息，作为迁移完成后的比对基准。 | G6: 4.9 | H6: 同组·前端行 | I6: 同组·测试行 | J6: 7.1.1 | K6: Wade/DevB / 11/06
A7: F01-05 | B7: 模块1·存量历史数据迁移与标准化 | C7: 确保迁移过程数据完整可追溯 | D7: 迁移完整性校验 | E7: 迁移后完整性比对 | F7: 迁移完成后对源端与目标端数据进行完整性比对，识别缺失、损坏或异常变更。 | G7: 4.10 | H7: 同组·前端行 | I7: 同组·测试行 | J7: 7.1.1 | K7: Wade/DevB / 11/09
A8: F02-01 | B8: 模块2·实时数据接入与常态化数据治理 | C8: 多源异构数据接入与元数据标准化规整 | D8: 元数据标准与来源管理 | E8: 统一元数据模型 | F8: 建立统一元数据字段体系，明确字段定义、数据类型、取值规则和必填要求，包括来源系统、业务域、记录类型、创建时间、责任人、保留等级和密级等。 | G8: 4.11 | H8: 同组·前端行 | I8: 同组·测试行 | J8: 7.1.1 | K8: Wade/DevB / 11/10
A9: F02-02 | B9: 模块2·实时数据接入与常态化数据治理 | C9: 多源异构数据接入与元数据标准化规整 | D9: 元数据标准与来源管理 | E9: 来源系统信息绑定 | F9: 在记录接入和入库时引用统一源系统编码，并绑定退役项目、迁移批次等来源属性，支持按来源检索和统计。 | G9: 4.12 | H9: 同组·前端行 | I9: 同组·测试行 | J9: 7.1.1 | K9: Wade/DevB / 11/11
A10: F03-01 | B10: 模块3·记录归档与档案全生命周期管理 | C10: 归档记录定期删除与合规保留 | D10: 到期处置与Legal Hold管理 | E10: 保留期限到期自动删除 | F10: 根据预设保留策略，对到期归档记录执行自动删除或标记销毁。 | G10: 5.1 | H10: 同组·前端行 | I10: 同组·测试行 | J10: 7.1.1 | K10: Wade/DevB / 11/18
A11: F03-02 | B11: 模块3·记录归档与档案全生命周期管理 | C11: 归档记录定期删除与合规保留 | D11: 到期处置与Legal Hold管理 | E11: Legal Hold 冻结 | F11: 对涉诉、审计或合规调查中的记录设置Legal Hold，暂停删除和修改。 | G11: 5.2 | H11: 同组·前端行 | I11: 同组·测试行 | J11: 7.1.1 | K11: Wade/DevB / 11/20
A12: F04-01 | B12: 模块4·数据存储与境内数据安全管控 | C12: 满足数据不出境和本地化合规要求 | D12: 数据加密与密钥管理 | E12: 数据加密存储 | F12: 支持归档数据在存储和传输过程中的加密保护，防止未授权读取和数据泄露。 | G12: 5.3 | H12: 同组·前端行 | I12: 同组·测试行 | J12: 7.1.1 | K12: Wade/DevB / 11/23
A13: F04-02 | B13: 模块4·数据存储与境内数据安全管控 | C13: 满足数据不出境和本地化合规要求 | D13: 数据加密与密钥管理 | E13: 密钥管理 | F13: 支持加密密钥的创建、保管、更新、权限控制和操作审计。 | G13: 5.4 | H13: 同组·前端行 | I13: 同组·测试行 | J13: 7.1.1 | K13: Wade/DevB / 11/24
... A28: F08-05 | B28: 模块8·系统全局治理、运维与监控 | C28: 企业用户统一身份认证与系统访问 | D28: SSO 单点登录 | E28: 登录状态与异常访问控制 | F28: 对用户登录状态及认证异常进行基础控制，认证失效或账号不可用时限制系统访问。 | G28: 4.5 | H28: 同组·前端行 | I28: 同组·测试行 | J28: 7.1.1 | K28: Wade/DevB / 10/27
A29: 覆盖校验：源文件Scope-Phase1共26项功能，逐项对照WBS开发/协作/走查/测试任务，26/26全覆盖 ✓（本页由源文件自动解析生成，功能名与源文件完全一致）

Sheet 功能视角分解
A1: 功能视角分解（功能×角色矩阵）· V2.1排期口径（直估×AI执行系数）：每个功能由谁做什么 — 与WBS分解V2.1完全对账（合计212.3人天，窗口至2026/12/31）
A2: 功能编号 | B2: 模块 | C2: 具体功能（与源文件一致） | D2: BA·需求（Mandy） | E2: BA人天 | F2: 开发A·Wade | G2: A人天 | H2: 开发B·DevB | I2: B人天 | J2: 测试·验证（Mandy） | K2: 测试人天 | L2: 文档（Mandy） | M2: 文档人天 | N2: 小计人天 | O2: 关联WBS任务 | P2: 计划完成
A3: F01-01 | B3: 模块1·存量迁移 | C3: 结构化历史数据批量导入 | D3: 迁移范围/映射规则澄清与验收标准 | E3: 1.31 | F3: 迁移任务管理界面（调度/进度） | G3: 4.57 | H3: SeaTunnel分片/限速/断点批量导入 | I3: 5.21 | J3: 导入用例+样本表验证 | K3: 2.25 | L3: SLC文档 | M3: 0.75 | N3: =ROUND(E3+G3+I3+K3+M3,2) | O3: 4.6 | P3: Wade/DevB / 10/30
A4: F01-02 | B4: 模块1·存量迁移 | C4: 非结构化文件及离线包批量导入 | D4: 文件来源与离线介质场景澄清 | E4: 0.38 | F4: 迁移任务界面（文件批次） | G4: 2.28 | H4: 多源文件/大文件/属性保留/包解析 | I4: 3.59 | J4: 导入与中断恢复用例 | K4: 1.65 | L4: SLC文档 | M4: 0.38 | N4: =ROUND(E4+G4+I4+K4+M4,2) | O4: 4.7 | P4: Wade/DevB / 11/03
A5: F01-03 | B5: 模块1·存量迁移 | C5: 数据导入规则配置 | D5: 源→标准字段映射规则定义 | E5: 0.75 | F5: 规则配置界面 | G5: 2.28 | H5: 规则配置服务（映射/转换/校验） | I5: 2.61 | J5: 规则执行用例 | K5: 1.35 | L5: SLC文档 | M5: 0.38 | N5: =ROUND(E5+G5+I5+K5+M5,2) | O5: 4.8 | P5: Wade/DevB / 11/05
A6: F01-04 | B6: 模块1·存量迁移 | C6: 迁移前完整性基准记录 | D6: 完整性基准口径定义 | E6: 0.38 | F6: 校验结果展示 | G6: 0.33 | H6: 迁移前基准记录（行数/校验和） | I6: 1.79 | J6: 基准记录用例 | K6: 0.6 | L6: SLC文档 | M6: 0.38 | N6: =ROUND(E6+G6+I6+K6+M6,2) | O6: 4.9 | P6: Wade/DevB / 11/06
A7: F01-05 | B7: 模块1·存量迁移 | C7: 迁移后完整性比对 | D7: 比对差异处理口径 | E7: 0.19 | F7: 比对结果展示 | G7: 0.65 | H7: 迁移后比对（SHA-256/差异报告） | I7: 1.63 | J7: 比对用例（CC对账预演） | K7: 0.75 | L7: SLC文档 | M7: 0.38 | N7: =ROUND(E7+G7+I7+K7+M7,2) | O7: 4.10 | P7: Wade/DevB / 11/09
A8: F02-01 | B8: 模块2·元数据 | C8: 统一元数据模型 | D8: 元数据字段体系与必填规则 | E8: 1.31 | F8: — | G8: 2.6 | H8: 统一元数据模型API | I8: 0.66 | J8: 模块2走查 | K8: 0.75 | L8: SLC文档 | M8: 0.38 | N8: =ROUND(E8+G8+I8+K8+M8,2) | O8: 4.11 | P8: Wade/DevB / 11/10
A9: F02-02 | B9: 模块2·元数据 | C9: 来源系统信息绑定 | D9: 来源系统编码与绑定规则 | E9: 0.38 | F9: 元数据管理界面（协作） | G9: 1.3 | H9: 来源系统信息绑定API | I9: 0.82 | J9: 模块2走查 | K9: 0.75 | L9: SLC文档 | M9: 0.38 | N9: =ROUND(E9+G9+I9+K9+M9,2) | O9: 4.12 | P9: Wade/DevB / 11/11
A10: F03-01 | B10: 模块3·生命周期处置 | C10: 保留期限到期自动删除 | D10: 保留期矩阵与到期处置策略 | E10: 0.75 | F10: 保留策略配置界面 | G10: 1.63 | H10: 处置引擎（扫描→DROP PARTITION→VACUUM） | I10: 2.61 | J10: 到期删除走查 | K10: 1.2 | L10: SLC文档 | M10: 0.38 | N10: =ROUND(E10+G10+I10+K10+M10,2) | O10: 5.1 | P10: Wade/DevB / 11/18
A11: F03-02 | B11: 模块3·生命周期处置 | C11: Legal Hold 冻结 | D11: Legal Hold审批流程定义 | E11: 0.56 | F11: Legal Hold冻结/解除界面 | G11: 1.96 | H11: Hold/Release+豁免+留痕 | I11: 0.32 | J11: 冻结/解除走查 | K11: 0.9 | L11: SLC文档 | M11: 0.38 | N11: =ROUND(E11+G11+I11+K11+M11,2) | O11: 5.2 | P11: Wade/DevB / 11/20
A12: F04-01 | B12: 模块4·存储安全 | C12: 数据加密存储 | D12: 密级与加密合规要求 | E12: 0.38 | F12: — | G12: 0.98 | H12: ADLS原生SSE/CMK配置+PII字段级加密 | I12: 0.82 | J12: 加密落盘验证 | K12: 0.9 | L12: SLC文档 | M12: 0.38 | N12: =ROUND(E12+G12+I12+K12+M12,2) | O12: 5.3 | P12: Wade/DevB / 11/23
A13: F04-02 | B13: 模块4·存储安全 | C13: 密钥管理 | D13: 密钥保管与审计要求 | E13: 0.19 | F13: — | G13: 0.32 | H13: Key Vault原生(RBAC)+应用Managed Identity集成 | I13: 0.49 | J13: 密钥轮换用例 | K13: 0.75 | L13: SLC文档 | M13: 0.38 | N13: =ROUND(E13+G13+I13+K13+M13,2) | O13: 5.4 | P13: Wade/DevB / 11/24
A14: F04-03 | B14: 模块4·存储安全 | C14: 数据备份管理 | D14: 备份策略要求（RPO） | E14: 0.38 | F14: — | G14: 0.65 | H14: SQL PITR/ADLS原生备份策略配置 | I14: 0.82 | J14: 备份恢复用例 | K14: 0.75 | L14: SLC文档 | M14: 0.38 | N14: =ROUND(E14+G14+I14+K14+M14,2) | O14: 5.5 | P14: Wade/DevB / 11/25
A15: F04-04 | B15: 模块4·存储安全 | C15: 异地灾备 | D15: 灾备要求（RTO） | F15: — | H15: Azure Blob原生冗余(GRS)配置+恢复演练 | J15: 灾备切换用例 | L15: SLC文档 | N15: =ROUND(E15+G15+I15+K15+M15,2) | O15: —（Azure原生GRS，配置在3.2.7方案） | P15: DevB / 11/09
A16: F05-01 | B16: 模块5·检索利用 | C16: 关键词检索 | D16: 检索需求与查询配置模型 | E16: 0.38 | F16: 检索页动态表单+关键词检索 | G16: 1.63 | H16: — | I16: 1.62 | J16: 检索用例 | K16: 0.9 | L16: SLC文档 | M16: 0.38 | N16: =ROUND(E16+G16+I16+K16+M16,2) | O16: 5.6 | P16: Wade/DevB / 11/26
A17: F05-02 | B17: 模块5·检索利用 | C17: 按系统名称检索 | D17: 来源系统筛选需求 | F17: 按系统名称检索 | G17: 0.82 | H17: — | J17: 筛选用例 | K17: 0.3 | L17: SLC文档 | M17: 0.19 | N17: =ROUND(E17+G17+I17+K17+M17,2) | O17: 5.8 | P17: Wade/DevB / 11/27
A18: F05-03 | B18: 模块5·检索利用 | C18: 按业务时间检索 | D18: 时间维度检索需求 | F18: 按业务时间检索 | G18: 0.82 | H18: — | J18: 时间范围用例 | K18: 0.3 | L18: SLC文档 | M18: 0.19 | N18: =ROUND(E18+G18+I18+K18+M18,2) | O18: 5.9 | P18: Wade/DevB / 11/30
A19: F05-04 | B19: 模块5·检索利用 | C19: 检索结果列表展示 | D19: 列表字段/排序/导出需求 | F19: 结果列表（分页/排序）+流式导出 | G19: 1.46 | H19: — | I19: 0.49 | J19: 大批量用例 | K19: 0.6 | L19: SLC文档 | M19: 0.38 | N19: =ROUND(E19+G19+I19+K19+M19,2) | O19: 5.10 | P19: Wade/DevB / 11/30
A20: F05-05 | B20: 模块5·检索利用 | C20: 原始文件在线预览 | D20: 预览格式与权限要求 | F20: 在线预览（SAS直连）+大文件优化 | G20: 1.31 | H20: — | I20: 1.95 | J20: 预览用例 | K20: 0.75 | L20: SLC文档 | M20: 0.38 | N20: =ROUND(E20+G20+I20+K20+M20,2) | O20: 5.11 | P20: Wade/DevB / 12/01
A21: F06-01 | B21: 模块6·审计合规 | C21: 归档操作日志记录 | D21: 审计合规要求（归档日志） | E21: 0.19 | F21: 归档操作日志+审计查询界面 | G21: 1.63 | H21: — | I21: 0.49 | J21: 审计走查 | K21: 0.75 | L21: SLC文档 | M21: 0.38 | N21: =ROUND(E21+G21+I21+K21+M21,2) | O21: 5.7 | P21: Wade/DevB / 12/03
A22: F06-02 | B22: 模块6·审计合规 | C22: 查询操作日志记录 | D22: 查询行为审计要求 | F22: 查询操作日志记录 | G22: 0.49 | H22: — | I22: 0.33 | J22: 审计走查 | K22: 0.45 | L22: SLC文档 | M22: 0.19 | N22: =ROUND(E22+G22+I22+K22+M22,2) | O22: 5.12 | P22: Wade/DevB / 12/03
A23: F06-03 | B23: 模块6·审计合规 | C23: 导出操作日志记录 | D23: 导出审计要求（范围/IP） | F23: 导出操作日志记录 | G23: 0.82 | H23: — | I23: 0.16 | J23: 审计走查 | K23: 0.45 | L23: SLC文档 | M23: 0.19 | N23: =ROUND(E23+G23+I23+K23+M23,2) | O23: 5.13 | P23: Wade/DevB / 12/04
A24: F08-01 | B24: 模块8·全局治理 | C24: 基础角色权限配置 | D24: 角色权限矩阵（RBAC）定义 | E24: 0.75 | F24: 角色权限配置（界面+API） | G24: 1.63 | H24: — | I24: 0.66 | J24: 越权用例 | K24: 0.9 | L24: SLC文档 | M24: 0.75 | N24: =ROUND(E24+G24+I24+K24+M24,2) | O24: 4.1 | P24: Wade/DevB / 10/21
A25: F08-02 | B25: 模块8·全局治理 | C25: 用户账号管理 | D25: 账号生命周期策略 | E25: 0.19 | F25: 用户账号管理（界面+API） | G25: 1.47 | H25: — | I25: 0.16 | J25: 账号用例 | K25: 0.45 | L25: SLC文档 | M25: 0.38 | N25: =ROUND(E25+G25+I25+K25+M25,2) | O25: 4.2 | P25: Wade/DevB / 10/22
A26: F08-03 | B26: 模块8·全局治理 | C26: 企业SSO集成 | D26: SSO对接需求（Entra ID） | E26: 0.19 | F26: SSO集成（Entra ID+MSAL中间件） | G26: 1.47 | H26: — | I26: 0.66 | J26: SSO登录用例 | K26: 1.05 | L26: SLC文档 | M26: 0.38 | N26: =ROUND(E26+G26+I26+K26+M26,2) | O26: 4.3 | P26: Wade/DevB / 10/26
A27: F08-04 | B27: 模块8·全局治理 | C27: 用户身份自动识别与关联 | D27: 身份映射规则 | E27: 0.38 | F27: 身份自动识别与关联 | G27: 0.16 | H27: — | I27: 0.82 | J27: 身份关联用例 | K27: 0.45 | L27: SLC文档 | M27: 0.19 | N27: =ROUND(E27+G27+I27+K27+M27,2) | O27: 4.4 | P27: Wade/DevB / 10/27
A28: F08-05 | B28: 模块8·全局治理 | C28: 登录状态与异常访问控制 | D28: 异常访问控制策略 | E28: 0.19 | F28: 超时/锁定/失效控制 | G28: 0.65 | H28: — | I28: 0.65 | J28: 异常登录用例 | K28: 0.6 | L28: SLC文档 | M28: 0.19 | N28: =ROUND(E28+G28+I28+K28+M28,2) | O28: 4.5 | P28: Wade/DevB / 10/27
A29: G1 | B29: 公共支撑 | C29: 需求与SRS（跨功能） | D29: 业务访谈/26项澄清/SRS生成评审M1/需求贯穿 | E29: 7.52 | F29: — | H29: — | J29: NFR可执行化/测试计划/AI用例首批试点 | K29: 2.73 | L29: — | N29: — | O29: =ROUND(E29+G29+I29+K29+M29,2) | P29: 2.1,2.2,2.3,2.4 | Q29: 12/25
A30: G2 | B30: 公共支撑 | C30: 工程初始化与部署基座（N1+N4-1/2/3） | D30: — | F30: 仓库/规范/前端骨架/四道门禁CI-CD/部署流水线/K8s清单 | G30: 6.39 | H30: 后端骨架/集群对接/测试环境先期部署 | I30: 2.75 | J30: 基座与门禁验证/测试环境验证 | K30: 1.5 | L30: 工程基座SLC | M30: 0.38 | N30: — | O30: =ROUND(E30+G30+I30+K30+M30,2) | P30: 3.3,3.4 | Q30: 10/09
A31: G3 | B31: 公共支撑 | C31: 架构与数据设计 | D31: — | F31: UC权限与查询模型/资源验收/架构终稿/外部评审#1/M2 | G31: 4.25 | H31: 四层表结构/DDL/分层设计/迁移方案/非功能设计 | I31: 9.05 | J31: — | L31: — | N31: — | O31: =ROUND(E31+G31+I31+K31+M31,2) | P31: 3.1,3.2 | Q31: 09/30
A32: G4 | B32: 公共支撑 | C32: 样本数据与MVP评审 | D32: — | F32: 样本端到端联调M3 | G32: 1 | H32: — | J32: 样本数据集/M3评审支持 | K32: 1.25 | L32: — | N32: — | O32: =ROUND(E32+G32+I32+K32+M32,2) | P32: 4.13 | Q32: 11/12
A33: G5 | B33: 公共支撑 | C33: 集成、质量治理与CC迁移演练 | D33: — | F33: N2治理A侧/集成联调/CC适配/缺陷收敛 | G33: 9.45 | H33: N2治理B侧/CC迁移演练/对账报告/增量接入框架 | I33: 12.28 | J33: 质量抽检/26项核对/系统测试轮1/UAT准备/M4 | K33: 6.75 | L33: 质量治理SLC | M33: 0.19 | N33: 冻结与就绪评审M5 | O33: =ROUND(E33+G33+I33+K33+M33+1,2) | P33: 5.15,6.1,6.2,6.3… | Q33: 12/28
A34: G6 | B34: 公共支撑 | C34: 系统测试与UAT | D34: — | F34: — | H34: — | J34: 全量测试/缺陷回归/UAT组织M6 | K34: 2.8 | L34: 测试报告+UAT报告+SLC合稿定稿 | M34: 0.75 | N34: — | O34: =ROUND(E34+G34+I34+K34+M34,2) | P34: 7.1 | Q34: 12/18
A35: G7 | B35: 公共支撑 | C35: 非功能专项与全局实现、开发侧文档 | D35: 鉴权掩码策略澄清 | E35: 0.19 | F35: N3前端性能/鉴权掩码前端/专项/N5架构接口文档 | G35: 6.77 | H35: N3数据性能/可观测/容量/迁移预跑/安全专项/N5数据文档 | I35: 8.3 | J35: N3专项用例 | K35: 1.5 | L35: N5合稿评审 | M35: 0.38 | N35: 生产就绪评审 | O35: =ROUND(E35+G35+I35+K35+M35+1,2) | P35: 5.14,7.2,7.3 | Q35: 12/28
A36: G8 | B36: 公共支撑 | C36: 部署上线与交付 | D36: 上线首日支持/业务确认 | E36: 1.5 | F36: 生产部署/上线验证/值守交接应用侧 | G36: 3 | H36: CC全量迁移/作业启动/值守交接数据侧 | I36: 3.25 | J36: 上线Checklist | K36: 0.75 | L36: 部署运维SLC/复盘 | M36: 0.38 | N36: 交付确认M7 | O36: =ROUND(E36+G36+I36+K36+M36,2) | P36: 8.1,8.2 | Q36: 12/31
A37: G9 | B37: 公共支撑 | C37: 项目管理（Mark） | D37: — | F37: — | H37: — | J37: — | L37: 会议纪要与项目文档整理 | M37: 0.75 | N37: 启动会/周例会/每日同步/进度风险跟踪/里程碑评审/收尾 | O37: =ROUND(E37+G37+I37+K37+M37+14.38,2) | P37: 1,1.2 | Q37: 12/31
A38: 合计 | C38: 26项功能 + 9类公共支撑 | D38: Mandy·BA | E38: =ROUND(SUM(E3:E37),2) | F38: Wade（开发A） | G38: =ROUND(SUM(G3:G37),2) | H38: DevB（开发B） | I38: =ROUND(SUM(I3:I37),2) | J38: Mandy·测试 | K38: =ROUND(SUM(K3:K37),2) | L38: Mandy·文档 | M38: =ROUND(SUM(M3:M37),2) | N38: =ROUND(SUM(N3:N37),2) | P38: PM Mark 16.380000000000003
A39: V2.1排期对账：Mandy三职 68.2（BA 18.44 + 测试 37.83 + 文档 11.930000000000001）+ Wade 64.76999999999998 + DevB 64.99 + PM 16.380000000000003 = 214.34人天，与「WBS分解」V2.1完全一致；全部人天=「功能拆解估算」直估×AI执行系数（AI生成×0.65/AI辅助×0.75/自动化×0.9/人工×1.0，测试左移×0.60）；直估原值297.5见拆解估算页；交付2026/12/31

Sheet 功能拆解估算
A1: 功能拆解估算（子任务级直估）：模块→功能→子任务三层结构，25项功能×72子任务 + 非功能与工程支撑×23子任务（F04-04异地灾备=Azure Blob原生能力，不计开发）— 独立估算，不锚定计划185人天；V2.1已按本表排期WBS（直估×AI执行系数=214.3人天，交付2026/12/31）
A2: 子任务编号 | B2: 模块 | C2: 功能/组名称 | D2: 子任务/工作包 | E2: 工作内容要点 | F2: BA人天 | G2: 开发A·Wade | H2: 开发B·DevB | I2: 测试人天 | J2: SLC人天（按功能） | K2: 小计 | L2: 功能/组小计
A3: F01-01-1 | B3: 模块1·存量历史数据迁移与标准化 | C3: 结构化历史数据批量导入 | D3: 原系统基本信息录入 | E3: 来源系统档案：系统编码/名称/业务域/责任人/退役批次；录入与维护界面+存储API | F3: 0.5 | G3: 1 | H3: 0.5 | I3: 0.5 | J3: 1 | K3: =ROUND(SUM(F3:I3),2) | L3: =ROUND(SUM(F3:I9)+J3,2)
A4: F01-01-2 | D4: 源库DB连接配置 | E4: DB类型/连接串录入，账号密码Key Vault加密存储，连通性测试 | F4: 0.25 | G4: 1.5 | H4: 1 | I4: 0.5 | K4: =ROUND(SUM(F4:I4),2)
A5: F01-01-3 | D5: 同步表勾选 | E5: 拉取源表清单、勾选同步范围、数据量预估与全选过滤 | F5: 0.25 | G5: 1.5 | H5: 1 | I5: 0.5 | K5: =ROUND(SUM(F5:I5),2)
A6: F01-01-4 | D6: 保留期限与迁移参数配置 | E6: 保留策略绑定、迁移批次命名、并发/限速参数 | F6: 0.5 | G6: 1 | H6: 0.5 | I6: 0.25 | K6: =ROUND(SUM(F6:I6),2)
A7: F01-01-5 | D7: 存储落地实现（Iceberg/UC） | E7: 磁盘目录布局、Iceberg表属性与分区策略、UC目录/Schema/授权配置化 | F7: 0.25 | H7: 2 | I7: 0.5 | K7: =ROUND(SUM(F7:I7),2)
A8: F01-01-6 | D8: SeaTunnel批量导入作业 | E8: 作业配置生成器、分片/断点续传/限速执行 | G8: 0.5 | H8: 2.5 | I8: 1 | K8: =ROUND(SUM(F8:I8),2)
A9: F01-01-7 | D9: 导入执行与监控 | E9: 任务状态/进度/失败重试/日志查看 | G9: 1.5 | H9: 0.5 | I9: 0.5 | K9: =ROUND(SUM(F9:I9),2)
A10: F01-02-1 | C10: 非结构化文件及离线包批量导入 | D10: 文件来源登记与上传通道 | E10: 在线上传/共享路径挂载/离线介质登记 | F10: 0.25 | G10: 2 | H10: 1 | I10: 0.5 | J10: 0.5 | K10: =ROUND(SUM(F10:I10),2) | L10: =ROUND(SUM(F10:I13)+J10,2)
A11: F01-02-2 | D11: 大文件分片上传与断点续传 | E11: 前端分片上传、后端合并与校验 | G11: 1.5 | H11: 1.5 | I11: 1 | K11: =ROUND(SUM(F11:I11),2)
A12: F01-02-3 | D12: 文件包解析 | E12: zip/tar/数据库备份包识别与展开、原始属性保留 | H12: 1.5 | I12: 0.75 | K12: =ROUND(SUM(F12:I12),2)
A13: F01-02-4 | D13: 附件元数据与Blob存储布局 | E13: 附件索引表、路径规范、与结构化记录关联 | F13: 0.25 | H13: 1.5 | I13: 0.5 | K13: =ROUND(SUM(F13:I13),2)
A14: F01-03-1 | C14: 数据导入规则配置 | D14: 字段映射规则配置 | E14: 源字段→标准字段映射界面、自动映射建议 | F14: 0.5 | G14: 2 | H14: 0.5 | I14: 0.5 | J14: 0.5 | K14: =ROUND(SUM(F14:I14),2) | L14: =ROUND(SUM(F14:I17)+J14,2)
A15: F01-03-2 | D15: 格式转换与清洗规则 | E15: 类型转换/编码/默认值/脏数据处理策略 | F15: 0.5 | H15: 1.5 | I15: 0.75 | K15: =ROUND(SUM(F15:I15),2)
A16: F01-03-3 | D16: 校验规则配置 | E16: 必填/唯一/范围/自定义表达式校验 | G16: 1 | H16: 1 | I16: 0.5 | K16: =ROUND(SUM(F16:I16),2)
A17: F01-03-4 | D17: 规则版本与试跑预览 | E17: 规则版本管理、样本试跑与结果预览 | G17: 0.5 | H17: 1 | I17: 0.5 | K17: =ROUND(SUM(F17:I17),2)
A18: F01-04-1 | C18: 迁移前完整性基准记录 | D18: 基准采集策略定义 | E18: 行数/校验和/SHA-256抽样口径 | F18: 0.5 | H18: 1 | I18: 0.25 | J18: 0.5 | K18: =ROUND(SUM(F18:I18),2) | L18: =ROUND(SUM(F18:I20)+J18,2)
A19: F01-04-2 | D19: 基准采集作业与存储 | E19: 源端基准快照生成、基准库表 | H19: 1.5 | I19: 0.5 | K19: =ROUND(SUM(F19:I19),2)
A20: F01-04-3 | D20: 基准报告查询展示 | E20: 基准结果展示与导出 | G20: 0.5 | H20: 0.25 | I20: 0.25 | K20: =ROUND(SUM(F20:I20),2)
A21: F01-05-1 | C21: 迁移后完整性比对 | D21: 比对引擎 | E21: RAW/CURATED逐层行数与校验和比对、抽样SHA-256 | H21: 2 | I21: 0.75 | J21: 0.5 | K21: =ROUND(SUM(F21:I21),2) | L21: =ROUND(SUM(F21:I22)+J21,2)
A22: F01-05-2 | D22: 差异报告与处理流程 | E22: 差异清单、重迁/豁免记录 | F22: 0.25 | G22: 1 | H22: 0.5 | I22: 0.5 | K22: =ROUND(SUM(F22:I22),2)
A23: F02-01-1 | B23: 模块2·实时数据接入与常态化数据治理 | C23: 统一元数据模型 | D23: 元数据字段体系定义 | E23: 字段/类型/必填/密级/保留等级字典 | F23: 1.5 | H23: 0.5 | I23: 0.25 | J23: 0.5 | K23: =ROUND(SUM(F23:I23),2) | L23: =ROUND(SUM(F23:I25)+J23,2)
A24: F02-01-2 | D24: 元数据核心表与API | E24: 核心元数据表实现、CRUD API、Migration | H24: 2 | I24: 0.5 | K24: =ROUND(SUM(F24:I24),2)
A25: F02-01-3 | D25: 元数据驱动配置机制 | E25: 查询配置模型、动态表单渲染协议 | F25: 0.25 | G25: 2 | H25: 0.5 | I25: 0.5 | K25: =ROUND(SUM(F25:I25),2)
A26: F02-02-1 | C26: 来源系统信息绑定 | D26: 绑定规则与批次属性 | E26: 源编码引用、退役项目/迁移批次属性规则 | F26: 0.5 | H26: 0.75 | I26: 0.25 | J26: 0.5 | K26: =ROUND(SUM(F26:I26),2) | L26: =ROUND(SUM(F26:I28)+J26,2)
A27: F02-02-2 | D27: 接入时自动绑定 | E27: 导入/上传时来源属性自动写入与校验 | H27: 1 | I27: 0.5 | K27: =ROUND(SUM(F27:I27),2)
A28: F02-02-3 | D28: 按来源检索与统计 | E28: 来源维度筛选、统计报表 | G28: 1 | H28: 0.5 | I28: 0.5 | K28: =ROUND(SUM(F28:I28),2)
A29: F03-01-1 | B29: 模块3·记录归档与档案全生命周期管理 | C29: 保留期限到期自动删除 | D29: 保留策略配置 | E29: 策略规则、继承关系、生效范围 | F29: 0.75 | G29: 1 | H29: 0.5 | I29: 0.5 | J29: 0.5 | K29: =ROUND(SUM(F29:I29),2) | L29: =ROUND(SUM(F29:I31)+J29,2)
A30: F03-01-2 | D30: 处置引擎 | E30: 到期扫描、豁免检查、DROP PARTITION、VACUUM物理清除 | H30: 3 | I30: 1 | K30: =ROUND(SUM(F30:I30),2)
A31: F03-01-3 | D31: 处置计划审批与台账 | E31: 预演清单、审批流、处置留痕台账 | F31: 0.25 | G31: 1.5 | H31: 0.5 | I31: 0.5 | K31: =ROUND(SUM(F31:I31),2)
A32: F03-02-1 | C32: Legal Hold 冻结 | D32: Hold申请与审批流程 | E32: 涉诉/审计/调查场景、审批链定义 | F32: 0.75 | G32: 1 | H32: 0.25 | I32: 0.5 | J32: 0.5 | K32: =ROUND(SUM(F32:I32),2) | L32: =ROUND(SUM(F32:I34)+J32,2)
A33: F03-02-2 | D33: Hold生效与解除实现 | E33: 记录级/表级冻结、处置豁免、操作留痕 | H33: 1.5 | I33: 0.75 | K33: =ROUND(SUM(F33:I33),2)
A34: F03-02-3 | D34: Hold清单管理与提醒 | E34: 在Hold清单、解除预警 | G34: 0.5 | H34: 0.25 | I34: 0.25 | K34: =ROUND(SUM(F34:I34),2)
A35: F04-01-1 | B35: 模块4·数据存储与境内数据安全管控 | C35: 数据加密存储 | D35: 加密策略定义 | E35: SSE+CMK方案、PII字段清单与字段级加密规则 | F35: 0.5 | H35: 0.75 | I35: 0.25 | J35: 0.5 | K35: =ROUND(SUM(F35:I35),2) | L35: =ROUND(SUM(F35:I37)+J35,2)
A36: F04-01-2 | D36: 存储层加密落地【原生】 | E36: ADLS SSE+CMK为存储账户原生选项：启用/托管密钥绑定/轮换/传输加密验证（配置为主） | H36: 0.5 | I36: 0.5 | K36: =ROUND(SUM(F36:I36),2)
A37: F04-01-3 | D37: PII字段级加密服务 | E37: 应用层加解密、密文索引策略、传输加密验证 | H37: 1.5 | I37: 0.75 | K37: =ROUND(SUM(F37:I37),2)
A38: F04-02-1 | C38: 密钥管理 | D38: 密钥全流程管理【原生】 | E38: Key Vault原生服务：创建/保管/轮换/吊销/权限=Key Vault+RBAC配置；开发仅应用侧Managed Identity集成与密钥引用 | F38: 0.25 | H38: 0.5 | I38: 0.5 | J38: 0.5 | K38: =ROUND(SUM(F38:I38),2) | L38: =ROUND(SUM(F38:I40)+J38,2)
A39: F04-02-2 | D39: 密钥操作审计与告警【原生】 | E39: Key Vault诊断日志+Azure Monitor原生告警，开发仅对接审计页 | G39: 0.25 | H39: 0.25 | I39: 0.5 | K39: =ROUND(SUM(F39:I39),2)
A40: F04-02-3 | D40: 密钥状态展示（不自研管理界面）【原生】 | E40: 密钥操作走Azure门户/CLI+RBAC，不自研管理界面；系统内仅密钥状态只读展示 | G40: 0.25 | I40: 0.25 | K40: =ROUND(SUM(F40:I40),2)
...

Sheet 里程碑计划
A1: 里程碑计划（M1~M7 · V2.0直估重排 · 全部避开周末与假期 · 窗口至 2026/12/31）
A2: 里程碑 | B2: 日期 | C2: 星期 | D2: 交付物/成果 | E2: 退出条件（验收标准） | F2: 责任人
A3: M1 需求基线冻结 | B3: 2026/09/22（周二） | C3: 周二 | D3: SRS V1.0、基线确认单 | E3: SRS评审通过、业务方签字；26项优先级锁定；追踪矩阵建立（SRS含NFR基线） | F3: Mandy
A4: M2 设计评审通过+接口冻结 | B4: 2026/09/30（周三） | C4: 周三 | D4: 架构设计文档V1.0、接口定义、数据字典v1 | E4: 设计评审（含外部架构评审#1意见闭环）通过；模块接口冻结 | F4: Wade
A5: M3 样本数据端到端MVP | B5: 2026/11/05（周四） | C5: 周四 | D5: M3演示记录（登录→导入→湖仓四层→任务界面可视） | E5: 测试环境（K8s）先期部署就绪；批次1功能（F08/F01/F02）全链路演示通过；CI/CD四道门禁+部署流水线自动 | F5: Wade+DevB
A6: M4 26项功能编码完成 | B6: 2026/12/16（周三） | C6: 周三 | D6: 走查签字单、追踪矩阵26/26 | E6: 26项功能编码100%（含N3全局非功能）；各功能测试与走查全部签字；无P0缺陷 | F6: Mandy
A7: M5 代码冻结+CC演练对账通过 | B7: 2026/12/25（周五） | C7: 周五 | D7: 全量对账报告、冻结基线、迁移Runbook | E7: CC迁移演练完成（600~800表，行数/校验和100%）；P0/P1缺陷清零；质量治理（N2）清零达标 | F7: DevB
A8: M6 系统测试+UAT签字 | B8: 2026/12/17（周四） | C8: 周四 | D8: 系统测试报告、UAT报告、SLC文档V1.0 | E8: 全量测试26项+非功能指标达标（对照NFR基线）；业务方UAT签字；性能/安全/迁移预跑专项通过 | F8: Mandy
A9: M7 生产上线·项目交付 | B9: 2026/12/31（周四） | C9: 周四 | D9: 生产系统、终版对账报告、交付确认单 | E9: 生产部署+CC全量迁移对账通过；核心场景业务确认；交付物归档完成 | F9: 全员
A11: 注：V2.1按「功能拆解估算」排期，人天=直估×AI执行系数（AI生成+人工审核×0.7／AI辅助×0.8／自动化流水线×0.9／人工主导×1.0，见J列与Q列直估对照）；DevB溢出按复查块既定路径消化（6项中间件/查询任务移Wade、增量接入移上线后首月）；交付锁定2026年内（12/30，12/31为缓冲）。

Sheet 资源负荷与日历
A1: 资源负荷（人天）与排期日历
A2: 负责人 | B2: P1管理 | C2: P2需求 | D2: P3设计与基座 | E2: P4开发一批次1 | F2: P5开发二批次2 | G2: P6集成·治理·CC演练 | H2: P7测试UAT与就绪 | I2: P8上线 | J2: 合计 | K2: 可用工作日 | L2: 负荷率/说明
A3: Mark | B3: =IF(ROUND(SUMPRODUCT(('WBS分解'!$C$4:$C$347=3)*('WBS分解'!$E$4:$E$347="Mark")*(LEFT('WBS分解'!$A$4:$A$347,1)="1")*'WBS分解'!$I$4:$I$347),2)=0,"",ROUND(SUMPRODUCT(('WBS分解'!$C$4:$C$347=3)*('WBS分解'!$E$4:$E$347="Mark")*(LEFT('WBS分解'!$A$4:$A$347,1)="1")*'WBS分解'!$I$4:$I$347),2)) | C3: =IF(ROUND(SUMPRODUCT(('WBS分解'!$C$4:$C$347=3)*('WBS分解'!$E$4:$E$347="Mark")*(LEFT('WBS分解'!$A$4:$A$347,1)="2")*'WBS分解'!$I$4:$I$347),2)=0,"",ROUND(SUMPRODUCT(('WBS分解'!$C$4:$C$347=3)*('WBS分解'!$E$4:$E$347="Mark")*(LEFT('WBS分解'!$A$4:$A$347,1)="2")*'WBS分解'!$I$4:$I$347),2)) | D3: =IF(ROUND(SUMPRODUCT(('WBS分解'!$C$4:$C$347=3)*('WBS分解'!$E$4:$E$347="Mark")*(LEFT('WBS分解'!$A$4:$A$347,1)="3")*'WBS分解'!$I$4:$I$347),2)=0,"",ROUND(SUMPRODUCT(('WBS分解'!$C$4:$C$347=3)*('WBS分解'!$E$4:$E$347="Mark")*(LEFT('WBS分解'!$A$4:$A$347,1)="3")*'WBS分解'!$I$4:$I$347),2)) | E3: =IF(ROUND(SUMPRODUCT(('WBS分解'!$C$4:$C$347=3)*('WBS分解'!$E$4:$E$347="Mark")*(LEFT('WBS分解'!$A$4:$A$347,1)="4")*'WBS分解'!$I$4:$I$347),2)=0,"",ROUND(SUMPRODUCT(('WBS分解'!$C$4:$C$347=3)*('WBS分解'!$E$4:$E$347="Mark")*(LEFT('WBS分解'!$A$4:$A$347,1)="4")*'WBS分解'!$I$4:$I$347),2)) | F3: =IF(ROUND(SUMPRODUCT(('WBS分解'!$C$4:$C$347=3)*('WBS分解'!$E$4:$E$347="Mark")*(LEFT('WBS分解'!$A$4:$A$347,1)="5")*'WBS分解'!$I$4:$I$347),2)=0,"",ROUND(SUMPRODUCT(('WBS分解'!$C$4:$C$347=3)*('WBS分解'!$E$4:$E$347="Mark")*(LEFT('WBS分解'!$A$4:$A$347,1)="5")*'WBS分解'!$I$4:$I$347),2)) | G3: =IF(ROUND(SUMPRODUCT(('WBS分解'!$C$4:$C$347=3)*('WBS分解'!$E$4:$E$347="Mark")*(LEFT('WBS分解'!$A$4:$A$347,1)="6")*'WBS分解'!$I$4:$I$347),2)=0,"",ROUND(SUMPRODUCT(('WBS分解'!$C$4:$C$347=3)*('WBS分解'!$E$4:$E$347="Mark")*(LEFT('WBS分解'!$A$4:$A$347,1)="6")*'WBS分解'!$I$4:$I$347),2)) | H3: =IF(ROUND(SUMPRODUCT(('WBS分解'!$C$4:$C$347=3)*('WBS分解'!$E$4:$E$347="Mark")*(LEFT('WBS分解'!$A$4:$A$347,1)="7")*'WBS分解'!$I$4:$I$347),2)=0,"",ROUND(SUMPRODUCT(('WBS分解'!$C$4:$C$347=3)*('WBS分解'!$E$4:$E$347="Mark")*(LEFT('WBS分解'!$A$4:$A$347,1)="7")*'WBS分解'!$I$4:$I$347),2)) | I3: =IF(ROUND(SUMPRODUCT(('WBS分解'!$C$4:$C$347=3)*('WBS分解'!$E$4:$E$347="Mark")*(LEFT('WBS分解'!$A$4:$A$347,1)="8")*'WBS分解'!$I$4:$I$347),2)=0,"",ROUND(SUMPRODUCT(('WBS分解'!$C$4:$C$347=3)*('WBS分解'!$E$4:$E$347="Mark")*(LEFT('WBS分解'!$A$4:$A$347,1)="8")*'WBS分解'!$I$4:$I$347),2)) | J3: =ROUND(SUM(B3:I3),2) | K3: PM排期16.4人天（直估15+冻结/就绪评审主持2×折算）；窗口73个工作日
A4: Mandy | B4: =IF(ROUND(SUMPRODUCT(('WBS分解'!$C$4:$C$347=3)*('WBS分解'!$E$4:$E$347="Mandy")*(LEFT('WBS分解'!$A$4:$A$347,1)="1")*'WBS分解'!$I$4:$I$347),2)=0,"",ROUND(SUMPRODUCT(('WBS分解'!$C$4:$C$347=3)*('WBS分解'!$E$4:$E$347="Mandy")*(LEFT('WBS分解'!$A$4:$A$347,1)="1")*'WBS分解'!$I$4:$I$347),2)) | C4: =IF(ROUND(SUMPRODUCT(('WBS分解'!$C$4:$C$347=3)*('WBS分解'!$E$4:$E$347="Mandy")*(LEFT('WBS分解'!$A$4:$A$347,1)="2")*'WBS分解'!$I$4:$I$347),2)=0,"",ROUND(SUMPRODUCT(('WBS分解'!$C$4:$C$347=3)*('WBS分解'!$E$4:$E$347="Mandy")*(LEFT('WBS分解'!$A$4:$A$347,1)="2")*'WBS分解'!$I$4:$I$347),2)) | D4: =IF(ROUND(SUMPRODUCT(('WBS分解'!$C$4:$C$347=3)*('WBS分解'!$E$4:$E$347="Mandy")*(LEFT('WBS分解'!$A$4:$A$347,1)="3")*'WBS分解'!$I$4:$I$347),2)=0,"",ROUND(SUMPRODUCT(('WBS分解'!$C$4:$C$347=3)*('WBS分解'!$E$4:$E$347="Mandy")*(LEFT('WBS分解'!$A$4:$A$347,1)="3")*'WBS分解'!$I$4:$I$347),2)) | E4: =IF(ROUND(SUMPRODUCT(('WBS分解'!$C$4:$C$347=3)*('WBS分解'!$E$4:$E$347="Mandy")*(LEFT('WBS分解'!$A$4:$A$347,1)="4")*'WBS分解'!$I$4:$I$347),2)=0,"",ROUND(SUMPRODUCT(('WBS分解'!$C$4:$C$347=3)*('WBS分解'!$E$4:$E$347="Mandy")*(LEFT('WBS分解'!$A$4:$A$347,1)="4")*'WBS分解'!$I$4:$I$347),2)) | F4: =IF(ROUND(SUMPRODUCT(('WBS分解'!$C$4:$C$347=3)*('WBS分解'!$E$4:$E$347="Mandy")*(LEFT('WBS分解'!$A$4:$A$347,1)="5")*'WBS分解'!$I$4:$I$347),2)=0,"",ROUND(SUMPRODUCT(('WBS分解'!$C$4:$C$347=3)*('WBS分解'!$E$4:$E$347="Mandy")*(LEFT('WBS分解'!$A$4:$A$347,1)="5")*'WBS分解'!$I$4:$I$347),2)) | G4: =IF(ROUND(SUMPRODUCT(('WBS分解'!$C$4:$C$347=3)*('WBS分解'!$E$4:$E$347="Mandy")*(LEFT('WBS分解'!$A$4:$A$347,1)="6")*'WBS分解'!$I$4:$I$347),2)=0,"",ROUND(SUMPRODUCT(('WBS分解'!$C$4:$C$347=3)*('WBS分解'!$E$4:$E$347="Mandy")*(LEFT('WBS分解'!$A$4:$A$347,1)="6")*'WBS分解'!$I$4:$I$347),2)) | H4: =IF(ROUND(SUMPRODUCT(('WBS分解'!$C$4:$C$347=3)*('WBS分解'!$E$4:$E$347="Mandy")*(LEFT('WBS分解'!$A$4:$A$347,1)="7")*'WBS分解'!$I$4:$I$347),2)=0,"",ROUND(SUMPRODUCT(('WBS分解'!$C$4:$C$347=3)*('WBS分解'!$E$4:$E$347="Mandy")*(LEFT('WBS分解'!$A$4:$A$347,1)="7")*'WBS分解'!$I$4:$I$347),2)) | I4: =IF(ROUND(SUMPRODUCT(('WBS分解'!$C$4:$C$347=3)*('WBS分解'!$E$4:$E$347="Mandy")*(LEFT('WBS分解'!$A$4:$A$347,1)="8")*'WBS分解'!$I$4:$I$347),2)=0,"",ROUND(SUMPRODUCT(('WBS分解'!$C$4:$C$347=3)*('WBS分解'!$E$4:$E$347="Mandy")*(LEFT('WBS分解'!$A$4:$A$347,1)="8")*'WBS分解'!$I$4:$I$347),2)) | J4: =ROUND(SUM(B4:I4),2) | K4: V2.1排期68.2人天（直估98×AI执行系数：测试左移×0.60/SLC×0.75等）；窗口73个工作日，负荷率93%
A5: Wade | B5: =IF(ROUND(SUMPRODUCT(('WBS分解'!$C$4:$C$347=3)*('WBS分解'!$E$4:$E$347="Wade")*(LEFT('WBS分解'!$A$4:$A$347,1)="1")*'WBS分解'!$I$4:$I$347),2)=0,"",ROUND(SUMPRODUCT(('WBS分解'!$C$4:$C$347=3)*('WBS分解'!$E$4:$E$347="Wade")*(LEFT('WBS分解'!$A$4:$A$347,1)="1")*'WBS分解'!$I$4:$I$347),2)) | C5: =IF(ROUND(SUMPRODUCT(('WBS分解'!$C$4:$C$347=3)*('WBS分解'!$E$4:$E$347="Wade")*(LEFT('WBS分解'!$A$4:$A$347,1)="2")*'WBS分解'!$I$4:$I$347),2)=0,"",ROUND(SUMPRODUCT(('WBS分解'!$C$4:$C$347=3)*('WBS分解'!$E$4:$E$347="Wade")*(LEFT('WBS分解'!$A$4:$A$347,1)="2")*'WBS分解'!$I$4:$I$347),2)) | D5: =IF(ROUND(SUMPRODUCT(('WBS分解'!$C$4:$C$347=3)*('WBS分解'!$E$4:$E$347="Wade")*(LEFT('WBS分解'!$A$4:$A$347,1)="3")*'WBS分解'!$I$4:$I$347),2)=0,"",ROUND(SUMPRODUCT(('WBS分解'!$C$4:$C$347=3)*('WBS分解'!$E$4:$E$347="Wade")*(LEFT('WBS分解'!$A$4:$A$347,1)="3")*'WBS分解'!$I$4:$I$347),2)) | E5: =IF(ROUND(SUMPRODUCT(('WBS分解'!$C$4:$C$347=3)*('WBS分解'!$E$4:$E$347="Wade")*(LEFT('WBS分解'!$A$4:$A$347,1)="4")*'WBS分解'!$I$4:$I$347),2)=0,"",ROUND(SUMPRODUCT(('WBS分解'!$C$4:$C$347=3)*('WBS分解'!$E$4:$E$347="Wade")*(LEFT('WBS分解'!$A$4:$A$347,1)="4")*'WBS分解'!$I$4:$I$347),2)) | F5: =IF(ROUND(SUMPRODUCT(('WBS分解'!$C$4:$C$347=3)*('WBS分解'!$E$4:$E$347="Wade")*(LEFT('WBS分解'!$A$4:$A$347,1)="5")*'WBS分解'!$I$4:$I$347),2)=0,"",ROUND(SUMPRODUCT(('WBS分解'!$C$4:$C$347=3)*('WBS分解'!$E$4:$E$347="Wade")*(LEFT('WBS分解'!$A$4:$A$347,1)="5")*'WBS分解'!$I$4:$I$347),2)) | G5: =IF(ROUND(SUMPRODUCT(('WBS分解'!$C$4:$C$347=3)*('WBS分解'!$E$4:$E$347="Wade")*(LEFT('WBS分解'!$A$4:$A$347,1)="6")*'WBS分解'!$I$4:$I$347),2)=0,"",ROUND(SUMPRODUCT(('WBS分解'!$C$4:$C$347=3)*('WBS分解'!$E$4:$E$347="Wade")*(LEFT('WBS分解'!$A$4:$A$347,1)="6")*'WBS分解'!$I$4:$I$347),2)) | H5: =IF(ROUND(SUMPRODUCT(('WBS分解'!$C$4:$C$347=3)*('WBS分解'!$E$4:$E$347="Wade")*(LEFT('WBS分解'!$A$4:$A$347,1)="7")*'WBS分解'!$I$4:$I$347),2)=0,"",ROUND(SUMPRODUCT(('WBS分解'!$C$4:$C$347=3)*('WBS分解'!$E$4:$E$347="Wade")*(LEFT('WBS分解'!$A$4:$A$347,1)="7")*'WBS分解'!$I$4:$I$347),2)) | I5: =IF(ROUND(SUMPRODUCT(('WBS分解'!$C$4:$C$347=3)*('WBS分解'!$E$4:$E$347="Wade")*(LEFT('WBS分解'!$A$4:$A$347,1)="8")*'WBS分解'!$I$4:$I$347),2)=0,"",ROUND(SUMPRODUCT(('WBS分解'!$C$4:$C$347=3)*('WBS分解'!$E$4:$E$347="Wade")*(LEFT('WBS分解'!$A$4:$A$347,1)="8")*'WBS分解'!$I$4:$I$347),2)) | J5: =ROUND(SUM(B5:I5),2) | K5: V2.1排期64.8人天（直估80.5×AI执行系数；另承接DevB瓶颈迁移的8项应用/中间件任务）；窗口73个工作日，负荷率89%
A6: DevB | B6: =IF(ROUND(SUMPRODUCT(('WBS分解'!$C$4:$C$347=3)*('WBS分解'!$E$4:$E$347="DevB")*(LEFT('WBS分解'!$A$4:$A$347,1)="1")*'WBS分解'!$I$4:$I$347),2)=0,"",ROUND(SUMPRODUCT(('WBS分解'!$C$4:$C$347=3)*('WBS分解'!$E$4:$E$347="DevB")*(LEFT('WBS分解'!$A$4:$A$347,1)="1")*'WBS分解'!$I$4:$I$347),2)) | C6: =IF(ROUND(SUMPRODUCT(('WBS分解'!$C$4:$C$347=3)*('WBS分解'!$E$4:$E$347="DevB")*(LEFT('WBS分解'!$A$4:$A$347,1)="2")*'WBS分解'!$I$4:$I$347),2)=0,"",ROUND(SUMPRODUCT(('WBS分解'!$C$4:$C$347=3)*('WBS分解'!$E$4:$E$347="DevB")*(LEFT('WBS分解'!$A$4:$A$347,1)="2")*'WBS分解'!$I$4:$I$347),2)) | D6: =IF(ROUND(SUMPRODUCT(('WBS分解'!$C$4:$C$347=3)*('WBS分解'!$E$4:$E$347="DevB")*(LEFT('WBS分解'!$A$4:$A$347,1)="3")*'WBS分解'!$I$4:$I$347),2)=0,"",ROUND(SUMPRODUCT(('WBS分解'!$C$4:$C$347=3)*('WBS分解'!$E$4:$E$347="DevB")*(LEFT('WBS分解'!$A$4:$A$347,1)="3")*'WBS分解'!$I$4:$I$347),2)) | E6: =IF(ROUND(SUMPRODUCT(('WBS分解'!$C$4:$C$347=3)*('WBS分解'!$E$4:$E$347="DevB")*(LEFT('WBS分解'!$A$4:$A$347,1)="4")*'WBS分解'!$I$4:$I$347),2)=0,"",ROUND(SUMPRODUCT(('WBS分解'!$C$4:$C$347=3)*('WBS分解'!$E$4:$E$347="DevB")*(LEFT('WBS分解'!$A$4:$A$347,1)="4")*'WBS分解'!$I$4:$I$347),2)) | F6: =IF(ROUND(SUMPRODUCT(('WBS分解'!$C$4:$C$347=3)*('WBS分解'!$E$4:$E$347="DevB")*(LEFT('WBS分解'!$A$4:$A$347,1)="5")*'WBS分解'!$I$4:$I$347),2)=0,"",ROUND(SUMPRODUCT(('WBS分解'!$C$4:$C$347=3)*('WBS分解'!$E$4:$E$347="DevB")*(LEFT('WBS分解'!$A$4:$A$347,1)="5")*'WBS分解'!$I$4:$I$347),2)) | G6: =IF(ROUND(SUMPRODUCT(('WBS分解'!$C$4:$C$347=3)*('WBS分解'!$E$4:$E$347="DevB")*(LEFT('WBS分解'!$A$4:$A$347,1)="6")*'WBS分解'!$I$4:$I$347),2)=0,"",ROUND(SUMPRODUCT(('WBS分解'!$C$4:$C$347=3)*('WBS分解'!$E$4:$E$347="DevB")*(LEFT('WBS分解'!$A$4:$A$347,1)="6")*'WBS分解'!$I$4:$I$347),2)) | H6: =IF(ROUND(SUMPRODUCT(('WBS分解'!$C$4:$C$347=3)*('WBS分解'!$E$4:$E$347="DevB")*(LEFT('WBS分解'!$A$4:$A$347,1)="7")*'WBS分解'!$I$4:$I$347),2)=0,"",ROUND(SUMPRODUCT(('WBS分解'!$C$4:$C$347=3)*('WBS分解'!$E$4:$E$347="DevB")*(LEFT('WBS分解'!$A$4:$A$347,1)="7")*'WBS分解'!$I$4:$I$347),2)) | I6: =IF(ROUND(SUMPRODUCT(('WBS分解'!$C$4:$C$347=3)*('WBS分解'!$E$4:$E$347="DevB")*(LEFT('WBS分解'!$A$4:$A$347,1)="8")*'WBS分解'!$I$4:$I$347),2)=0,"",ROUND(SUMPRODUCT(('WBS分解'!$C$4:$C$347=3)*('WBS分解'!$E$4:$E$347="DevB")*(LEFT('WBS分解'!$A$4:$A$347,1)="8")*'WBS分解'!$I$4:$I$347),2)) | J6: =ROUND(SUM(B6:I6),2) | K6: V2.1排期65.0人天（直估104×AI执行系数：ETL/SQL/作业AI生成为主）；窗口73个工作日，负荷率89%（原关键瓶颈，经迁移+折算化解）
A7: 合计 | B7: =ROUND(SUM(B3:B6),2) | C7: =ROUND(SUM(C3:C6),2) | D7: =ROUND(SUM(D3:D6),2) | E7: =ROUND(SUM(E3:E6),2) | F7: =ROUND(SUM(F3:F6),2) | G7: =ROUND(SUM(G3:G6),2) | H7: =ROUND(SUM(H3:H6),2) | I7: =ROUND(SUM(I3:I6),2) | J7: =ROUND(SUM(J3:J6),2) | K7: V2.1排期合计214.3人天=直估297.5×AI执行系数（AI生成×0.65/AI辅助×0.75/自动化×0.9/人工×1.0/测试左移×0.60）；DevB瓶颈经8项任务移Wade+增量接入/复盘文档移上线后化解；交付锁定2026/12/31
A9: 排期日历
A10: 项目窗口 | B10: 2026/9/14（周一）→ 2026/12/31（周四）交付（V2.1：直估×AI执行系数排期，不跨年；12/28~31为部署与迁移窗口）
A11: 假期扣除 | B11: 中秋9/25（五）；国庆10/1（四）~10/7（三）；备用赶工日9/20（日）、10/10（六）逢周末不排
A12: 周末 | B12: 每周六/日不排任务；官方调休补班日 9/20（日）、10/10（六）逢周末亦不排，可作备用赶工日
A13: 外部依赖（4项）
A14: ① CC只读账号 | B14: 9/18提交申请（3.2.3）→ 最迟11/13交付，11/16 CC迁移演练（6.2.1）依赖；责任人DevB；超承诺日3天升级管理层
A15: ② 平台资源交付 | B15: ADLS/Databricks/Key Vault等，9/30验收（3.3.3）；责任人Wade
A16: ③ 业务方UAT排期 | B16: 11/25确认（6.3.4），12/7 UAT执行（7.1.3）；责任人Mandy
A17: ④ 生产窗口审批 | B17: 12/9前完成审批，12/10生产部署（8.1.1）；责任人Mark
A18: 外部评审人（风险缓解） | B18: 外部架构评审#1：10/9（与M2设计评审同日）；外部关键模块评审#2：11/11（RBAC/掩码/加密/处置引擎）；每次2~4小时

Sheet WBS词典
A1: WBS词典（关键工作包定义与验收标准）· V2.0直估重排
A2: WBS编号 | B2: 任务名称 | C2: 工作包定义 | D2: 交付物 | E2: 验收标准 | F2: 负责人 | G2: 前置条件
A3: 1.1.1 | B3: 项目启动会与AI Native开发模式对齐 | C3: 宣布项目范围/里程碑/四道门禁规则/RACI，全员对齐AI协作规约（代码AI生成、人工审核、门禁硬卡点）。 | D3: 启动会纪要、RACI矩阵 | E3: 全员签认AI协作规约；门禁规则（不可bypass）获管理层背书 | F3: Mark | G3: 团队3人+PM到岗；AI工具账号就绪
A4: 2.2.2 | B4: SRS评审与需求基线冻结◆M1 | C4: 26项功能+非功能需求（NFR）基线评审冻结，后续变更走变更流程。 | D4: SRS V1.0、基线确认单 | E4: 业务方签字；26项优先级锁定；追踪矩阵建立 | F4: Mandy | G4: 访谈与澄清完成（2.1）
A5: 2.3.1 | B5: NFR测试可执行化 | C5: 将SRS中NFR基线细化为可测验收标准：检索响应/导出吞吐/并发/越权与掩码旁路用例口径。 | D5: NFR可执行化清单 | E5: 每项NFR均有可执行用例与达标口径 | F5: Mandy | G5: M1冻结
A6: 3.2.1 | B6: 目标数据模型预设计 | C6: RAW→CURATED→LAKE→SERVE四层表结构草案，支撑600~800表规模。 | D6: 四层模型草案 | E6: 架构组评审通过 | F6: DevB | G6: SRS初稿（2.2.1）
A7: 3.2.6 | B7: F01迁移方案定稿 | C7: SeaTunnel配置生成器方案+四层转换规则（类型映射/清洗/分区归约）。 | D7: 迁移方案文档 | E7: 样本表走查验证方案可行 | F7: DevB | G7: 湖仓分层设计（3.2.4）
A8: 3.2.7 | B8: F04与非功能设计定稿 | C8: 加密/密钥/备份灾备方案（Azure原生：SSE+CMK/Key Vault/PITR/GRS）+性能容量与「数据不出境」合规基线。 | D8: 非功能设计说明 | E8: 合规法务确认；原生组件清单落定（对照拆解估算③） | F8: DevB | G8: NFR可执行化（2.3.1）
A9: 3.1.5 | B9: 设计评审通过+模块接口冻结◆M2 | C9: 总体架构终稿+模块接口定义评审（含外部架构评审#1意见闭环），接口冻结。 | D9: 设计评审纪要 | E9: 评审通过；接口变更走变更流程 | F9: Wade | G9: 架构终稿+数据设计定稿
A10: 3.3.6 | B10: 四道安全门禁CI/CD搭建 | C10: Azure DevOps流水线：构建+镜像+SAST静态扫描/依赖扫描/密钥扫描/越权与掩码旁路用例四道硬门禁，任何合入必须过门禁。 | D10: CI/CD流水线（4道硬门禁） | E10: 演示一次拦截样例；门禁不可bypass（含紧急发布） | F10: Wade | G10: Azure DevOps权限就绪
A11: 3.4.6 | B11: 测试环境先期部署（N4-3） | C11: Azure DevOps经Service Connection连接K8s（命名空间RBAC授权）后，测试环境早期先部署，供联调/集成/系统测试，随迭代由流水线自动更新；生产环境终期部署（带审批门禁），不用Helm。 | D11: 测试环境（K8s） | E11: 测试环境可由流水线一键自动部署更新 | F11: DevB | G11: 部署流水线（N4-1）就绪
A12: 4.13.3 | B12: 样本端到端联调◆M3（批次1 MVP） | C12: 登录→导入→湖仓四层落地→任务界面可视，在测试环境（K8s）做端到端演示，提前暴露分层/权限模型方向性错误。 | D12: M3演示记录 | E12: 全链路演示通过；测试环境流水线自动部署 | F12: Wade+DevB | G12: 批次1（F08/F01/F02）开发完成；N4-3就绪
A13: 4.6.15 | B13: SeaTunnel批量导入作业（F01-01） | C13: 作业配置生成器、分片/断点续传/限速执行，600~800表规模样本验证。 | D13: 导入作业+样本验证记录 | E13: 断点续传与限速演示通过；对账口径落定 | F13: DevB | G13: 迁移方案定稿（3.2.6）
... A21: 8.2.8 | B21: 生产上线成功·项目交付完成◆M7 | C21: 交付确认与总结会。 | D21: 交付确认单 | E21: 交付物归档完成；复盘文档定稿 | F21: 全员 | G21: 8.1生产部署与迁移完成

Sheet 进度汇总
A1: 项目进度汇总（自动统计）
A2: 统计项 | B2: 数值 | C2: 说明
A3: 任务总数（含各级汇总行） | B3: =COUNTA('WBS分解'!$A$4:$A$343) | C3: 按已填写WBS编号的行数统计
A4: 其中：一级任务数 | B4: =COUNTIF('WBS分解'!$C$4:$C$343,1) | C4: 层级=1 的行数
A5: 其中：工作包数（三级） | B5: =COUNTIF('WBS分解'!$C$4:$C$343,3) | C5: 层级=3 的行数
A6: 已完成 | B6: =COUNTIF('WBS分解'!$L$4:$L$343,"已完成")
A7: 进行中 | B7: =COUNTIF('WBS分解'!$L$4:$L$343,"进行中")
A8: 未开始 | B8: =COUNTIF('WBS分解'!$L$4:$L$343,"未开始")
A9: 已延期 | B9: =COUNTIF('WBS分解'!$L$4:$L$343,"已延期")
A10: 任务完成率 | B10: =IFERROR(COUNTIF('WBS分解'!$L$4:$L$343,"已完成")/COUNTA('WBS分解'!$A$4:$A$343),0) | C10: 已完成 ÷ 任务总数
A11: 整体平均进度 | B11: =AVERAGE('WBS分解'!$M$4:$M$343) | C11: 对进度列简单平均
A12: 工作量合计（人天·仅三级工作包） | B12: =SUMPRODUCT(('WBS分解'!$C$4:$C$343=3)*'WBS分解'!$I$4:$I$343) | C12: Mark 16.4 / Mandy 68.2 / Wade 64.8 / DevB 65.0（V2.1排期口径，合计214.3=直估297.5×AI执行系数）
A13: Mark 工作量（人天） | B13: =SUMPRODUCT(('WBS分解'!$C$4:$C$343=3)*('WBS分解'!$E$4:$E$343="Mark")*'WBS分解'!$I$4:$I$343) | C13: 约定15人天
A14: Mandy 工作量（人天） | B14: =SUMPRODUCT(('WBS分解'!$C$4:$C$343=3)*('WBS分解'!$E$4:$E$343="Mandy")*'WBS分解'!$I$4:$I$343) | C14: BA/测试/文档
A15: Wade 工作量（人天） | B15: =SUMPRODUCT(('WBS分解'!$C$4:$C$343=3)*('WBS分解'!$E$4:$E$343="Wade")*'WBS分解'!$I$4:$I$343) | C15: 开发A
A16: DevB 工作量（人天） | B16: =SUMPRODUCT(('WBS分解'!$C$4:$C$343=3)*('WBS分解'!$E$4:$E$343="DevB")*'WBS分解'!$I$4:$I$343) | C16: 开发B
A17: 预算合计（元） | B17: =SUM('WBS分解'!$O$4:$O$343) | C17: 未填列，可按需补充
A19: ※ 本页自动汇总自「WBS分解」表，请勿手工修改。
