Workbook

Sheet 使用说明
A1: WBS工作分解结构模板 — 使用说明
A3: 一、什么是WBS
B4: WBS（Work Breakdown Structure，工作分解结构）：把项目按「可交付成果」逐层分解，直到每一层都是可估算、可指派、可跟踪的工作包（Work Package）。
B5: 它是进度计划、成本预算、资源分配的基础——先有WBS，再排计划（甘特图）。
A7: 二、编制原则
A8: 1. 100%原则 | B8: 同一层级的子项之和 = 父项的全部工作：不多做（防镀金）、不漏做（防遗漏）。
A9: 2. 成果导向 | B9: 以交付物/成果命名（如「需求规格说明书」），避免只写动作（如「做需求」）。
A10: 3. MECE | B10: 同级任务相互独立、完全穷尽，不重叠、无遗漏。
A11: 4. 粒度适中 | B11: 工作包以 8～80 小时完成为宜（经验法则）；一个工作包只对应一个直接责任人。
A12: 5. 层级适度 | B12: 一般 3～4 层；大项目可先按阶段（Phase）划分，再按交付物细分。
A14: 三、编号规则
A15: 第一层 | B15: 1、2、3……（阶段或主要交付物）
A16: 第二层 | B16: 1.1、1.2……；第三层：1.1.1、1.1.2……，依此类推。
A17: 注意 | B17: 编号本身即表达层级与归属关系，请勿跳号、重号；建议以文本格式录入，避免被识别为小数。
A19: 四、模板使用步骤
A20: 步骤1 | B20: 在「WBS模板」表第2行填写项目名称、项目经理、编制日期与版本。
A21: 步骤2 | B21: 自上而下逐层分解：先列一级（阶段/交付物），再细分二级、三级工作包。
A22: 步骤3 | B22: 逐行补充交付物、负责人、起止日期；「工期」自动计算（含首尾日），无需手填。
A23: 步骤4 | B23: 用下拉框填「状态」「优先级」；「进度」填百分比（如 50%），自动显示数据条。
A24: 步骤5 | B24: 超期且未完成的任务行会自动标红提醒（见示例行 2.1.2）。
A25: 步骤6 | B25: 在「WBS词典」页为关键工作包补充定义与验收标准；「进度汇总」页自动统计出数。
A26: 步骤7 | B26: 正式使用时，删除第4行起的灰色示例数据即可（保留前3行标题）。
A28: 五、表格列说明
A29: WBS编号 | B29: 任务的层级编码，如 1.2.1。
A30: 任务名称 | B30: 以成果命名；单元格按层级自动缩进，结构一目了然。
A31: 层级 | B31: 1=第一层……用于表头筛选（如只看一级=项目里程碑视图）。
A32: 交付物/成果 | B32: 任务完成后产出的、可验证的成果物。
A33: 负责人 | B33: 该工作包的直接责任人（唯一）。
A34: 开始/结束日期 | B34: 格式 yyyy/m/d。
A35: 工期(天) | B35: 自动 = 结束日期 − 开始日期 + 1。
A36: 前置任务 | B36: 紧前工作的 WBS 编号；多个用分号隔开（如 4.1.2;4.2.2）。
A37: 状态 | B37: 下拉选择：未开始 / 进行中 / 已完成 / 已延期 / 暂停，自动着色。
A38: 进度 | B38: 0%–100% 的百分比，显示蓝色数据条。
A39: 优先级 | B39: 下拉选择：高 / 中 / 低。
A40: 预算/实际成本 | B40: 单位：元；建议只在最底层工作包填写，汇总页自动合计。
A41: 备注 | B41: 风险、假设、审批记录等补充信息。
A43: 六、实用技巧
A44: 筛选 | B44: 表头已开启自动筛选：可按层级、负责人、状态、优先级快速过滤。
A45: 新增行 | B45: 示例行下方预留了带公式和下拉的空白行；若需插行，请先「复制上一行」再粘贴，保留公式与格式。
A46: 里程碑 | B46: 用 1 天任务表示，名称后加 ◆ 标记（如示例中的 1.1.2、5.2.3）。
...

Sheet WBS模板
A1: 项目工作分解结构（WBS）表
A2: 项目名称：XX集团ERP升级项目（示例） | F2: 项目经理：王强 | I2: 编制日期：2026/9/1 | L2: 版本：V1.0 | N2: 项目状态：进行中
A3: WBS编号 | B3: 任务名称 | C3: 层级 | D3: 交付物/成果 | E3: 负责人 | F3: 开始日期 | G3: 结束日期 | H3: 工期(天) | I3: 前置任务 | J3: 状态 | K3: 进度 | L3: 优先级 | M3: 预算(元) | N3: 实际成本(元) | O3: 备注
A4: 1 | B4: 项目管理 | C4: 1 | D4: 项目管理计划、验收报告等 | E4: 王强 | F4: 46251 | G4: 46381 | H4: =IF(OR(F4="",G4=""),"",G4-F4+1) | J4: 进行中 | K4: 0.35 | L4: 高 | O4: 贯穿项目全周期
A5: 1.1 | B5: 项目启动 | C5: 2 | D5: 项目章程、启动会纪要 | E5: 王强 | F5: 46251 | G5: 46254 | H5: =IF(OR(F5="",G5=""),"",G5-F5+1) | J5: 已完成 | K5: 1 | L5: 高
A6: 1.1.1 | B6: 制定项目章程 | C6: 3 | D6: 项目章程（批准版） | E6: 王强 | F6: 46251 | G6: 46253 | H6: =IF(OR(F6="",G6=""),"",G6-F6+1) | J6: 已完成 | K6: 1 | L6: 高 | M6: 8000 | N6: 7600 | O6: 已获发起人签字
A7: 1.1.2 | B7: 召开项目启动会 ◆ | C7: 3 | D7: 启动会纪要 | E7: 王强 | F7: 46254 | G7: 46254 | H7: =IF(OR(F7="",G7=""),"",G7-F7+1) | I7: 1.1.1 | J7: 已完成 | K7: 1 | L7: 高 | M7: 2000 | N7: 1800 | O7: 里程碑，全体干系人参加
A8: 1.2 | B8: 项目规划 | C8: 2 | D8: 项目管理计划、基准文件 | E8: 王强 | F8: 46255 | G8: 46262 | H8: =IF(OR(F8="",G8=""),"",G8-F8+1) | J8: 已完成 | K8: 1 | L8: 高
A9: 1.2.1 | B9: 编制项目管理计划 | C9: 3 | D9: 项目管理计划 | E9: 王强 | F9: 46255 | G9: 46260 | H9: =IF(OR(F9="",G9=""),"",G9-F9+1) | I9: 1.1.2 | J9: 已完成 | K9: 1 | L9: 高 | M9: 12000 | N9: 12500
A10: 1.2.2 | B10: 制定进度与成本基准 | C10: 3 | D10: 进度基准、成本基准 | E10: 王强 | F10: 46261 | G10: 46262 | H10: =IF(OR(F10="",G10=""),"",G10-F10+1) | I10: 1.2.1 | J10: 已完成 | K10: 1 | L10: 高 | M10: 6000 | N10: 5800 | O10: 含本WBS基准
A11: 1.3 | B11: 项目执行监控 | C11: 2 | D11: 项目周报、风险登记册 | E11: 王强 | F11: 46274 | G11: 46374 | H11: =IF(OR(F11="",G11=""),"",G11-F11+1) | J11: 未开始 | K11: 0 | L11: 中
A12: 1.3.1 | B12: 周例会与进度跟踪 | C12: 3 | D12: 项目周报 | E12: 王强 | F12: 46274 | G12: 46374 | H12: =IF(OR(F12="",G12=""),"",G12-F12+1) | I12: 1.2.2 | J12: 未开始 | K12: 0 | L12: 中 | M12: 15000 | O12: 每周一上午
A13: 1.3.2 | B13: 风险与变更管理 | C13: 3 | D13: 风险登记册、变更日志 | E13: 王强 | F13: 46274 | G13: 46374 | H13: =IF(OR(F13="",G13=""),"",G13-F13+1) | J13: 未开始 | K13: 0 | L13: 中 | M13: 8000
A14: 1.4 | B14: 项目收尾 | C14: 2 | D14: 验收报告、总结报告 | E14: 王强 | F14: 46377 | G14: 46381 | H14: =IF(OR(F14="",G14=""),"",G14-F14+1) | J14: 未开始 | K14: 0 | L14: 中
A15: 1.4.1 | B15: 组织项目验收 | C15: 3 | D15: 验收报告（签字版） | E15: 王强 | F15: 46377 | G15: 46379 | H15: =IF(OR(F15="",G15=""),"",G15-F15+1) | I15: 6.2.2 | J15: 未开始 | K15: 0 | L15: 高 | M15: 5000
A16: 1.4.2 | B16: 经验教训总结 | C16: 3 | D16: 项目总结报告 | E16: 王强 | F16: 46380 | G16: 46381 | H16: =IF(OR(F16="",G16=""),"",G16-F16+1) | I16: 1.4.1 | J16: 未开始 | K16: 0 | L16: 低 | M16: 3000
A17: 2 | B17: 需求分析 | C17: 1 | D17: 需求规格说明书 | E17: 李娜 | F17: 46255 | G17: 46273 | H17: =IF(OR(F17="",G17=""),"",G17-F17+1) | J17: 进行中 | K17: 0.5 | L17: 高
A18: 2.1 | B18: 需求调研 | C18: 2 | D18: 访谈纪要、业务流程图 | E18: 李娜 | F18: 46255 | G18: 46265 | H18: =IF(OR(F18="",G18=""),"",G18-F18+1) | J18: 进行中 | K18: 0.85 | L18: 高
A19: 2.1.1 | B19: 关键用户访谈 | C19: 3 | D19: 访谈纪要 | E19: 李娜 | F19: 46255 | G19: 46259 | H19: =IF(OR(F19="",G19=""),"",G19-F19+1) | I19: 1.1.2 | J19: 已完成 | K19: 1 | L19: 高 | M19: 6000 | N19: 5800
A20: 2.1.2 | B20: 业务流程梳理 | C20: 3 | D20: 业务流程图 | E20: 李娜 | F20: 46260 | G20: 46265 | H20: =IF(OR(F20="",G20=""),"",G20-F20+1) | I20: 2.1.1 | J20: 进行中 | K20: 0.7 | L20: 高 | M20: 8000 | N20: 5500 | O20: 已超期：演示自动标红提醒
A21: 2.2 | B21: 需求定义 | C21: 2 | D21: 需求规格说明书 | E21: 李娜 | F21: 46266 | G21: 46273 | H21: =IF(OR(F21="",G21=""),"",G21-F21+1) | J21: 进行中 | K21: 0.05 | L21: 高
A22: 2.2.1 | B22: 编写需求规格说明书 | C22: 3 | D22: 需求规格说明书（V1.0） | E22: 李娜 | F22: 46266 | G22: 46269 | H22: =IF(OR(F22="",G22=""),"",G22-F22+1) | I22: 2.1.2 | J22: 进行中 | K22: 0.1 | L22: 高 | M22: 10000 | N22: 2000
A23: 2.2.2 | B23: 需求评审与基线确认 | C23: 3 | D23: 评审记录、基线确认单 | E23: 李娜 | F23: 46272 | G23: 46273 | H23: =IF(OR(F23="",G23=""),"",G23-F23+1) | I23: 2.2.1 | J23: 未开始 | K23: 0 | L23: 高 | M23: 4000 | O23: 需客户代表参加
A24: 3 | B24: 系统设计 | C24: 1 | D24: 架构/详细设计文档 | E24: 张伟 | F24: 46274 | G24: 46295 | H24: =IF(OR(F24="",G24=""),"",G24-F24+1) | J24: 未开始 | K24: 0 | L24: 高
A25: 3.1 | B25: 总体架构设计 | C25: 2 | D25: 选型报告、架构设计文档 | E25: 张伟 | F25: 46274 | G25: 46283 | H25: =IF(OR(F25="",G25=""),"",G25-F25+1) | J25: 未开始 | K25: 0 | L25: 高
A26: 3.1.1 | B26: 技术选型与验证 | C26: 3 | D26: 选型验证报告 | E26: 张伟 | F26: 46274 | G26: 46276 | H26: =IF(OR(F26="",G26=""),"",G26-F26+1) | I26: 2.2.2 | J26: 未开始 | K26: 0 | L26: 高 | M26: 8000
A27: 3.1.2 | B27: 系统架构设计 | C27: 3 | D27: 架构设计文档 | E27: 张伟 | F27: 46279 | G27: 46283 | H27: =IF(OR(F27="",G27=""),"",G27-F27+1) | I27: 3.1.1 | J27: 未开始 | K27: 0 | L27: 高 | M27: 15000
A28: 3.2 | B28: 详细设计 | C28: 2 | D28: 数据模型、接口规范、设计稿 | E28: 张伟 | F28: 46286 | G28: 46295 | H28: =IF(OR(F28="",G28=""),"",G28-F28+1) | J28: 未开始 | K28: 0 | L28: 中
A29: 3.2.1 | B29: 数据库设计 | C29: 3 | D29: ER图、数据字典 | E29: 张伟 | F29: 46286 | G29: 46288 | H29: =IF(OR(F29="",G29=""),"",G29-F29+1) | I29: 3.1.2 | J29: 未开始 | K29: 0 | L29: 中 | M29: 10000
A30: 3.2.2 | B30: 接口设计 | C30: 3 | D30: 接口规范文档 | E30: 陈杰 | F30: 46289 | G30: 46293 | H30: =IF(OR(F30="",G30=""),"",G30-F30+1) | I30: 3.2.1 | J30: 未开始 | K30: 0 | L30: 中 | M30: 8000
A31: 3.2.3 | B31: UI/UX设计 | C31: 3 | D31: 交互原型、视觉设计稿 | E31: 赵敏 | F31: 46286 | G31: 46295 | H31: =IF(OR(F31="",G31=""),"",G31-F31+1) | I31: 3.1.2 | J31: 未开始 | K31: 0 | L31: 中 | M31: 20000
A32: 4 | B32: 开发实施 | C32: 1 | D32: 可运行的系统 | E32: 陈杰 | F32: 46304 | G32: 46353 | H32: =IF(OR(F32="",G32=""),"",G32-F32+1) | J32: 未开始 | K32: 0 | L32: 高 | O32: 排期避开国庆假期
A33: 4.1 | B33: 前端开发 | C33: 2 | D33: 前端代码 | E33: 赵敏 | F33: 46304 | G33: 46339 | H33: =IF(OR(F33="",G33=""),"",G33-F33+1) | J33: 未开始 | K33: 0 | L33: 高
A34: 4.1.1 | B34: 前端框架搭建 | C34: 3 | D34: 前端脚手架工程 | E34: 赵敏 | F34: 46304 | G34: 46307 | H34: =IF(OR(F34="",G34=""),"",G34-F34+1) | I34: 3.2.3 | J34: 未开始 | K34: 0 | L34: 高 | M34: 10000
A35: 4.1.2 | B35: 页面与功能开发 | C35: 3 | D35: 前端页面代码 | E35: 赵敏 | F35: 46308 | G35: 46339 | H35: =IF(OR(F35="",G35=""),"",G35-F35+1) | I35: 4.1.1 | J35: 未开始 | K35: 0 | L35: 高 | M35: 40000
A36: 4.2 | B36: 后端开发 | C36: 2 | D36: 后端服务 | E36: 陈杰 | F36: 46304 | G36: 46339 | H36: =IF(OR(F36="",G36=""),"",G36-F36+1) | J36: 未开始 | K36: 0 | L36: 高
A37: 4.2.1 | B37: 后端框架搭建 | C37: 3 | D37: 后端脚手架工程 | E37: 陈杰 | F37: 46304 | G37: 46307 | H37: =IF(OR(F37="",G37=""),"",G37-F37+1) | I37: 3.2.2 | J37: 未开始 | K37: 0 | L37: 高 | M37: 10000
A38: 4.2.2 | B38: 业务逻辑与接口开发 | C38: 3 | D38: 后端服务代码 | E38: 陈杰 | F38: 46308 | G38: 46339 | H38: =IF(OR(F38="",G38=""),"",G38-F38+1) | I38: 4.2.1 | J38: 未开始 | K38: 0 | L38: 高 | M38: 50000
A39: 4.3 | B39: 联调与单元测试 | C39: 2 | D39: 联调记录、单测报告 | E39: 陈杰 | F39: 46342 | G39: 46353 | H39: =IF(OR(F39="",G39=""),"",G39-F39+1) | J39: 未开始 | K39: 0 | L39: 高
A40: 4.3.1 | B40: 前后端联调 | C40: 3 | D40: 联调记录 | E40: 陈杰 | F40: 46342 | G40: 46346 | H40: =IF(OR(F40="",G40=""),"",G40-F40+1) | I40: 4.1.2;4.2.2 | J40: 未开始 | K40: 0 | L40: 高 | M40: 8000
...

Sheet WBS词典
A1: WBS词典（工作包定义）
A2: WBS编号 | B2: 任务名称 | C2: 工作内容描述 | D2: 交付物 | E2: 验收标准 | F2: 责任人 | G2: 假设与前提 | H2: 备注
A3: 2.2.1 | B3: 编写需求规格说明书 | C3: 汇总调研结果，按公司模板编写功能需求与非功能需求，并组织内部预评审。 | D3: 需求规格说明书（V1.0基线） | E3: 覆盖全部业务范围；通过评审并由客户代表签字确认。 | F3: 李娜 | G3: 需求调研已全部完成 | H3: 评审会预留半天
A4: 3.2.1 | B4: 数据库设计 | C4: 基于批准的架构完成概念、逻辑、物理模型设计，编制数据字典与索引方案。 | D4: ER图、数据字典、建表脚本 | E4: 满足第三范式（反范式设计需书面说明理由）；通过架构组评审。 | F4: 张伟 | G4: 架构设计文档已批准 | H4: 核心表预留扩展字段
A5: 4.2.2 | B5: 业务逻辑与接口开发 | C5: 按接口规范实现全部业务接口，包含参数校验、异常处理与操作日志。 | D5: 后端服务代码（含单元测试） | E5: 联调全部通过；单元测试覆盖率 ≥ 70%；无阻塞性缺陷。 | F5: 陈杰 | G5: 接口规范已冻结 | H5: 核心交易类接口优先
A6: 5.2.3 | B6: 用户验收测试(UAT) | C6: 组织关键用户按业务场景执行UAT，记录问题并跟踪闭环。 | D6: UAT报告、问题清单 | E6: P0/P1级问题全部关闭；用户代表签署UAT结论。 | F6: 李娜 | G6: 功能/性能测试已通过 | H6: 预留1天回归窗口
A7: 6.2.1 | B7: 系统部署与数据迁移 | C7: 执行正式发布：部署应用、迁移历史数据并核对一致性，验证通过后开放访问。 | D7: 上线记录、数据核对报告 | E7: 数据迁移核对差异率为0；回退方案演练就绪。 | F7: 张伟 | G7: 生产环境已准备完毕 | H7: 迁移窗口：夜间22:00后

Sheet 进度汇总
A1: 项目进度汇总（自动统计）
A2: 统计项 | B2: 数值 | C2: 说明
A3: 任务总数（含各级汇总行） | B3: =COUNTA('WBS模板'!$A$4:$A$100) | C3: 按已填写WBS编号的行数统计
A4: 其中：一级任务数 | B4: =COUNTIF('WBS模板'!$C$4:$C$100,1) | C4: 层级=1 的行数
A5: 已完成 | B5: =COUNTIF('WBS模板'!$J$4:$J$100,"已完成")
A6: 进行中 | B6: =COUNTIF('WBS模板'!$J$4:$J$100,"进行中")
A7: 未开始 | B7: =COUNTIF('WBS模板'!$J$4:$J$100,"未开始")
A8: 已延期 | B8: =COUNTIF('WBS模板'!$J$4:$J$100,"已延期")
A9: 暂停 | B9: =COUNTIF('WBS模板'!$J$4:$J$100,"暂停")
A10: 任务完成率 | B10: =IFERROR(COUNTIF('WBS模板'!$J$4:$J$100,"已完成")/COUNTA('WBS模板'!$A$4:$A$100),0) | C10: 已完成 ÷ 任务总数
A11: 整体平均进度 | B11: =IFERROR(AVERAGE('WBS模板'!$K$4:$K$100),0) | C11: 对已填进度行简单平均
A12: 预算合计（元） | B12: =SUM('WBS模板'!$M$4:$M$100) | C12: 建议只在最底层工作包填预算
A13: 实际成本合计（元） | B13: =SUM('WBS模板'!$N$4:$N$100)
A14: 成本偏差（预算-实际） | B14: =B12-B13 | C14: 正数=结余，负数=超支
A15: ※ 本页数据自动汇总自「WBS模板」表（第4–100行），请勿手工修改。
